Workbook

Sheet Financial Summary
A2: Company Name | B2: FirstEnergy Corp (FE.N)
A3: Country of Exchange | B3: United States of America
A4: Country of Headquarters | B4: United States of America
A5: TRBC Industry Group | B5: Electric Utilities & IPPs
A6: CF Template | B6: IND
A7: Consolidation Basis | B7: Consolidated
A8: Scaling | B8: Millions
A9: Period | B9: Annual
A10: Export Date | B10: 45975.878
A11: Statement Data | B11: 2024 | C11: 2023 | D11: 2022 | E11: 2021 | F11: 2020 | G11: 2019 | H11: 2018 | I11: 2017 | J11: 2016 | K11: 2015
A12: Period End Date | B12: 45657 | C12: 45291 | D12: 44926 | E12: 44561 | F12: 44196 | G12: 43830 | H12: 43465 | I12: 43100 | J12: 42735 | K12: 42369
A13: Statement Date | B13: 45656 | C13: 45290 | D13: 44925 | E13: 44560 | F13: 44195 | G13: 43829 | H13: 43464 | I13: 43464 | J13: 43464 | K13: 42368
A14: Standardized Currency | B14: USD | C14: USD | D14: USD | E14: USD | F14: USD | G14: USD | H14: USD | I14: USD | J14: USD | K14: USD
A15: Template Type | B15: Industrial - Operating | C15: Industrial - Operating | D15: Industrial - Operating | E15: Industrial - Operating | F15: Industrial - Operating | G15: Industrial - Operating | H15: Industrial - Operating | I15: Industrial - Operating | J15: Industrial - Operating | K15: Industrial - Operating
A16: Period End FX Rate | B16: 1.438 | C16: 1.3245 | D16: 1.3549 | E16: 1.2634 | F16: 1.273 | G16: 1.2986 | H16: 1.3637 | I16: 1.2577 | J16: 1.343 | K16: 1.3839
A17: Avg. FX Rate | B17: 1.370032 | C17: 1.3493112 | D17: 1.3016236 | E17: 1.2534562 | F17: 1.3408481 | G17: 1.3264151 | H17: 1.2960156 | I17: 1.2975704 | J17: 1.3248434 | K17: 1.278554
A19: Financial Summary - Standardized (Currency: Canadian Dollar)
A20: Field Name | B20: 30-12-2024 | C20: 30-12-2023 | D20: 30-12-2022 | E20: 30-12-2021 | F20: 30-12-2020 | G20: 30-12-2019 | H20: 30-12-2018 | I20: 30-12-2017 | J20: 30-12-2016 | K20: 30-12-2015
A21: Selected Per Share Data
A22: Dividend Yield - Common Stock - Gross - Issue Specific - % | B22: 4.27 | C22: 4.36 | D22: 3.72 | E22: 3.75 | F22: 5.1 | G22: 3.15 | H22: 4.85 | I22: 4.7 | J22: 4.65 | K22: 4.54
A23: Dividend Yield - Common Stock - Net - Issue Specific - % | B23: 4.27 | C23: 4.36 | D23: 3.72 | E23: 3.75 | F23: 5.1 | G23: 3.15 | H23: 4.85 | I23: 4.7 | J23: 4.65 | K23: 4.54
A24: Shares used to calculate Diluted EPS - Total | B24: 577 | C24: 574 | D24: 572 | E24: 546 | F24: 543 | G24: 542 | H24: 494 | I24: 444 | J24: 426 | K24: 424
A25: Profitability / Return
A26: Gross Profit Margin - % | B26: 55.78 | C26: 52.55 | D26: 52.1 | E26: 57.36 | F26: 59.74 | G26: 57.92 | H26: 57.53 | I26: 59.28 | J26: 55.01 | K26: 50.39
A27: EBITDA Margin - % | B27: 29.42 | C27: 28.96 | D27: 26.37 | E27: 28.91 | F27: 31.84 | G27: 33.8 | H27: 32.38 | I27: 31.99 | J27: 28.32 | K27: 29.81
A28: Operating Margin - % | B28: 17.63 | C28: 17.61 | D28: 15.33 | E28: 14.53 | F28: 20.04 | G28: 22.75 | H28: 22.22 | I28: 22.59 | J28: 19.6 | K28: 16.66
A29: Income before Tax Margin - % | B29: 11.16 | C29: 11.38 | D29: 11.55 | E29: 14 | F29: 10.46 | G29: 10.12 | H29: 13.43 | I29: 13.05 | J29: 10.07 | K29: 5.94
A30: Income Tax Rate - % | B30: 25.07 | C30: 18.24 | D30: 69.49 | E30: 20.53 | F30: 11.16 | G30: 19.07 | H30: 30.82 | I30: 36.61 | J30: 48.89 | K30: 35.27
A31: Net Margin - % | B31: 8.37 | C31: 9.3 | D31: 3.52 | E31: 11.13 | F31: 9.3 | G31: 8.19 | H31: 9.29 | I31: 8.27 | J31: 5.15 | K31: 3.85
A32: Return on Average Common Equity - % (Income available to Common excluding Extraordinary Items) | B32: 8.54 | C32: 10.9 | D32: 4.31 | E32: 15.57 | F32: 14.11 | G32: 13.12 | H32: 12.73 | I32: 17.78 | J32: 5.91 | K32: 4.65
A33: Return on Average Total Assets - % (Income before Discontinued Operations & Extraordinary Items) | B33: 2.24 | C33: 2.52 | D33: 0.96 | E33: 2.76 | F33: 2.31 | G33: 2.2 | H33: 2.54 | I33: 2.12 | J33: 1.16 | K33: 1.11
A34: Return on Invested Capital - % | B34: 4.72 | C34: 5.7 | D34: 2.15 | E34: 6.63 | F34: 6.56 | G34: 6.23 | H34: 8.34 | I34: -4.29 | J34: -18.07 | K34: 3.6
A35: Growth
A36: Common Shares - Outstanding - Total | B36: 576.61 | C36: 574.34 | D36: 572.13 | E36: 570.26 | F36: 543.12 | G36: 540.65 | H36: 511.92 | I36: 445.33 | J36: 442.34 | K36: 423.56
A37: Financial Strength / Leverage
A38: Total Debt Percentage of Total Assets | B38: 46.16 | C38: 51.08 | D38: 46.96 | E38: 52.5 | F38: 55.05 | G38: 49.64 | H38: 48.68 | I38: 46.25 | J38: 52.27 | K38: 42.18
A39: Total Debt Percentage of Total Capital | B39: 63.65 | C39: 69.53 | D39: 67.05 | E39: 73.33 | F39: 77.18 | G39: 75.07 | H39: 74.11 | I39: 83.28 | J39: 78.32 | K39: 63.88
A40: Total Debt Percentage of Total Equity | B40: 175.09 | C40: 228.2 | D40: 203.46 | E40: 274.97 | F40: 338.22 | G40: 301.05 | H40: 286.23 | I40: 497.96 | J40: 361.35 | K40: 176.89
A41: Debt Service Percentage of Normalized after Tax Profit | B41: 223.91 | C41: 172.77 | D41: 368.68 | E41: 354.96 | F41: 192.64 | G41: 160.23 | H41: 198.03 | I41: 340.21 | J41: 651.58 | K41: 326.11
A42: Interest Coverage Ratio | B42: 2.35 | C42: 2.21 | D42: 2 | E42: 1.52 | F42: 2.19 | G42: 2.61 | H42: 2.38 | I42: 2.59 | J42: 2.28 | K42: 2.47
...

Sheet Income Statement
A1: Company Fundamentals - Income Statement
A2: Company Name | B2: FirstEnergy Corp (FE.N)
A3: Country of Exchange | B3: United States of America
A4: Country of Headquarters | B4: United States of America
A5: TRBC Industry Group | B5: Electric Utilities & IPPs
A6: CF Template | B6: IND
A7: Consolidation Basis | B7: Consolidated
A8: Scaling | B8: Millions
A9: Period | B9: Annual
A10: Export Date | B10: 45975.878
A11: Statement Data | B11: 2024 | C11: 2023 | D11: 2022 | E11: 2021 | F11: 2020 | G11: 2019 | H11: 2018 | I11: 2017 | J11: 2016 | K11: 2015
A12: Period End Date | B12: 45657 | C12: 45291 | D12: 44926 | E12: 44561 | F12: 44196 | G12: 43830 | H12: 43465 | I12: 43100 | J12: 42735 | K12: 42369
A13: Statement Date | B13: 45656 | C13: 45290 | D13: 44925 | E13: 44560 | F13: 44195 | G13: 43829 | H13: 43464 | I13: 43464 | J13: 43464 | K13: 42368
A14: Standardized Currency | B14: USD | C14: USD | D14: USD | E14: USD | F14: USD | G14: USD | H14: USD | I14: USD | J14: USD | K14: USD
A15: Template Type | B15: Industrial - Operating | C15: Industrial - Operating | D15: Industrial - Operating | E15: Industrial - Operating | F15: Industrial - Operating | G15: Industrial - Operating | H15: Industrial - Operating | I15: Industrial - Operating | J15: Industrial - Operating | K15: Industrial - Operating
A16: Period End FX Rate | B16: 1.438 | C16: 1.3245 | D16: 1.3549 | E16: 1.2634 | F16: 1.273 | G16: 1.2986 | H16: 1.3637 | I16: 1.2577 | J16: 1.343 | K16: 1.3839
A17: Avg. FX Rate | B17: 1.370032 | C17: 1.3493112 | D17: 1.3016236 | E17: 1.2534562 | F17: 1.3408481 | G17: 1.3264151 | H17: 1.2960156 | I17: 1.2975704 | J17: 1.3248434 | K17: 1.278554
A19: Income Statement - Standardized (Currency: Canadian Dollar)
A20: Field Name | B20: 30-12-2024 | C20: 30-12-2023 | D20: 30-12-2022 | E20: 30-12-2021 | F20: 30-12-2020 | G20: 30-12-2019 | H20: 30-12-2018 | I20: 30-12-2017 | J20: 30-12-2016 | K20: 30-12-2015
A21: Revenues
A22: Revenue from Goods & Services | B22: 18457.07 | C22: 17365.64 | D22: 16216.93 | E22: 13953.47 | F22: 14467.75 | G22: 14636.99 | H22: 14594.43 | I22: 14179.85 | J22: 14175.82 | K22: 19211.55
A23: Utility Revenue - Total | B23: 18457.07 | C23: 17365.64 | D23: 16216.93 | E23: 13953.47 | F23: 14467.75 | G23: 14636.99 | H23: 14594.43 | I23: 14179.85 | J23: 14175.82 | K23: 19211.55
A24: Utility Revenue - Electric Operations | B24: 17980.3 | C24: 16804.32 | D24: 15331.82 | E24: 13307.94 | F24: 13812.08 | G24: 13569.23 | H24: 13312.67 | I24: 12965.32 | J24: 12994.06 | K24: 13598.7
A25: Utility Revenue - Non-Utility Operations | B25: 476.77 | C25: 561.31 | D25: 885.1 | E25: 645.53 | F25: 655.67 | G25: 1067.76 | H25: 1281.76 | I25: 1214.53 | J25: 1181.76 | K25: 5612.85
A26: Revenue from Business Activities - Total | B26: 18457.07 | C26: 17365.64 | D26: 16216.93 | E26: 13953.47 | F26: 14467.75 | G26: 14636.99 | H26: 14594.43 | I26: 14179.85 | J26: 14175.82 | K26: 19211.55
A27: Operating Expenses
A28: Cost of Operating Revenue | B28: 8161.28 | C28: 8240.24 | D28: 7768.09 | E28: 5950.16 | F28: 5824.64 | G28: 6159.87 | H28: 6198.84 | I28: 5774.19 | J28: 6377.8 | K28: 9531.62
A29: Cost of Revenues - Total | B29: 8161.28 | C29: 8240.24 | D29: 7768.09 | E29: 5950.16 | F29: 5824.64 | G29: 6159.87 | H29: 6198.84 | I29: 5774.19 | J29: 6377.8 | K29: 9531.62
A30: Depreciation in Cost of Revenues | B30: 2166.02 | C30: 1971.34 | D30: 1789.73 | E30: 1632 | F30: 1708.24 | G30: 1618.23 | H30: 1472.27 | I30: 1332.6 | J30: 1236.08 | K30: 1639.11
A31: Material Expenses | B31: 5995.26 | C31: 6268.9 | D31: 5978.36 | E31: 4318.16 | F31: 4116.4 | G31: 4541.65 | H31: 4726.57 | I31: 4441.58 | J31: 5141.72 | K31: 7892.51
A32: Utility Cost of Revenue - Fuel Expense | B32: 635.69 | C32: 725.93 | D32: 950.19 | E32: 602.91 | F32: 494.77 | G32: 659.23 | H32: 697.26 | I32: 644.89 | J32: 756.49 | K32: 2371.72
A33: Utility Cost of Revenue - Purchased Power | B33: 5359.57 | C33: 5542.97 | D33: 5028.17 | E33: 3715.24 | F33: 3621.63 | G33: 3882.42 | H33: 4029.31 | I33: 3796.69 | J33: 4385.23 | K33: 5520.8
A34: Gross Profit - Industrials/Property - Total | B34: 10295.79 | C34: 9125.39 | D34: 8448.84 | E34: 8003.32 | F34: 8643.11 | G34: 8477.12 | H34: 8395.59 | I34: 8405.66 | J34: 7798.03 | K34: 9679.93
A35: Selling, General & Administrative Expenses - Total | B35: 1660.48 | C35: 1570.6 | D35: 1469.53 | E35: 1344.96 | F35: 1482.98 | G35: 1402.02 | H35: 1286.94 | I35: 1219.72 | J35: 1209.58 | K35: 1250.43
A36: Selling, General & Administrative Expenses - Other - Total | B36: 1660.48 | C36: 1570.6 | D36: 1469.53 | E36: 1344.96 | F36: 1482.98 | G36: 1402.02 | H36: 1286.94 | I36: 1219.72 | J36: 1209.58 | K36: 1250.43
A37: Property & Other Taxes | B37: 1660.48 | C37: 1570.6 | D37: 1469.53 | E37: 1344.96 | F37: 1402.53 | G37: 1337.03 | H37: 1286.94 | I37: 1219.72 | J37: 1209.58 | K37: 1250.43
A38: Rental Expense | F38: 80.45 | G38: 64.99
A39: Other Operating Expense/(Income) - Net | B39: 5381.49 | C39: 4497.25 | D39: 4493.2 | E39: 4631.52 | F39: 4261.22 | G39: 3745.8 | H39: 3866.01 | I39: 3982.24 | J39: 3810.25 | K39: 5229.29
A40: Other Operating Income - Total | B40: 316.48 | C40: 352.17 | D40: 475.09 | F40: 71.06 | G40: 104.79 | H40: 194.4
A41: Other Operating Expense | B41: 5697.96 | C41: 4849.42 | D41: 4968.3 | E41: 4631.52 | F41: 4332.28 | G41: 3850.58 | H41: 4060.42 | I41: 3982.24 | J41: 3810.25 | K41: 5229.29
...

Sheet Cash Flow
A1: Company Fundamentals - Cash Flow
A2: Company Name | B2: FirstEnergy Corp (FE.N)
A3: Country of Exchange | B3: United States of America
A4: Country of Headquarters | B4: United States of America
A5: TRBC Industry Group | B5: Electric Utilities & IPPs
A6: CF Template | B6: IND
A7: Consolidation Basis | B7: Consolidated
A8: Scaling | B8: Millions
A9: Period | B9: Annual
A10: Export Date | B10: 45975.878
A11: Statement Data | B11: 2024 | C11: 2023 | D11: 2022 | E11: 2021 | F11: 2020 | G11: 2019 | H11: 2018 | I11: 2017 | J11: 2016 | K11: 2015
A12: Period End Date | B12: 45657 | C12: 45291 | D12: 44926 | E12: 44561 | F12: 44196 | G12: 43830 | H12: 43465 | I12: 43100 | J12: 42735 | K12: 42369
A13: Statement Date | B13: 45656 | C13: 45290 | D13: 44925 | E13: 44560 | F13: 44195 | G13: 43829 | H13: 43464 | I13: 43464 | J13: 43464 | K13: 43099
A14: Standardized Currency | B14: USD | C14: USD | D14: USD | E14: USD | F14: USD | G14: USD | H14: USD | I14: USD | J14: USD | K14: USD
A15: Template Type | B15: Industrial - Indirect | C15: Industrial - Indirect | D15: Industrial - Indirect | E15: Industrial - Indirect | F15: Industrial - Indirect | G15: Industrial - Indirect | H15: Industrial - Indirect | I15: Industrial - Indirect | J15: Industrial - Indirect | K15: Industrial - Indirect
A16: Period End FX Rate | B16: 1.438 | C16: 1.3245 | D16: 1.3549 | E16: 1.2634 | F16: 1.273 | G16: 1.2986 | H16: 1.3637 | I16: 1.2577 | J16: 1.343 | K16: 1.3839
A17: Avg. FX Rate | B17: 1.370032 | C17: 1.3493112 | D17: 1.3016236 | E17: 1.2534562 | F17: 1.3408481 | G17: 1.3264151 | H17: 1.2960156 | I17: 1.2975704 | J17: 1.3248434 | K17: 1.278554
A19: Cash Flow - Standardized (Currency: Canadian Dollar)
A20: Field Name | B20: 30-12-2024 | C20: 30-12-2023 | D20: 30-12-2022 | E20: 30-12-2021 | F20: 30-12-2020 | G20: 30-12-2019 | H20: 30-12-2018 | I20: 30-12-2017 | J20: 30-12-2016 | K20: 30-12-2015
A21: Operating Cash Flow - Indirect
A22: Profit/(Loss) - Starting Line - Cash Flow | B22: 1544.03 | C22: 1586.79 | D22: 571.41 | E22: 1608.18 | F22: 1446.78 | G22: 1209.69 | H22: 1747.03 | I22: -2237.01 | J22: -8183.56 | K22: 739
A23: Non-cash Items & Reconciliation Adjustments - Cash Flow | B23: 2957.9 | C23: 817.68 | D23: 2655.31 | E23: 1491.61 | F23: 488.07 | G23: 1887.49 | H23: 451.01 | I23: 7089.92 | J23: 12599.26 | K23: 3481.5
A24: Discontinued Operations - Gain/(Loss) - Net of Tax - Cash Flow - to Reconcile | C24: 28.34 | E24: -58.91 | F24: -101.9 | G24: -78.26 | H24: -563.77
A25: Other Non-Cash Items & Reconciliation Adjustments - Cash Flow - to Reconcile | B25: 349.36 | C25: -1277.8 | D25: -346.23 | E25: -691.91 | F25: -1169.22 | G25: 17.24 | H25: -1389.33 | I25: 659.17 | J25: -33.12 | K25: 852.8
A26: Depreciation, Depletion & Amortization including Impairment - Cash Flow - to Reconcile | B26: 2175.61 | C26: 1727.12 | D26: 1714.24 | E26: 2006.78 | F26: 1607.68 | G26: 1614.25 | H26: 1793.69 | I26: 5318.74 | J26: 16744.7 | K26: 2388.34
A27: Accretion of Asset Retirement Obligations - Cash Flow - to Reconcile | B27: 274.01
A28: Depreciation & Depletion - Property, Plant & Equipment - Cash Flow - to Reconcile | B28: 2175.61 | C28: 1727.12 | D28: 1714.24 | E28: 2006.78 | F28: 1607.68 | G28: 1614.25 | H28: 1793.69 | I28: 2205.87 | J28: 2615.24 | K28: 2334.64
A29: Impairment - Property, Plant & Equipment including Intangible Assets - Cash Flow - to Reconcile | I29: 3112.87 | J29: 14129.46 | K29: 53.7
A30: Deferred Income Taxes & Income Tax Credits - Cash Flow - to Reconcile | B30: 432.93 | C30: 340.03 | D30: 1287.31 | E30: 372.28 | F30: 151.52 | G30: 334.26 | H30: 628.57 | I30: 1088.66 | J30: -4058 | K30: 363.11
A31: Assets Sale - Gain/(Loss) - Cash Flow - to Reconcile | E31: -136.63 | H31: -11.66 | I31: -81.75 | J31: -66.24 | K31: -29.41
A32: Financial Assets - Unrealized Gain/(Loss) - Cash Flow - to Reconcile | H32: -6.48 | I32: 105.1 | J32: 11.92 | K32: -93.33
A33: Cash Flow from Operating Activities before Changes in Working Capital | B33: 4501.93 | C33: 2404.47 | D33: 3226.72 | E33: 3099.8 | F33: 1934.84 | G33: 3097.18 | H33: 2198.04 | I33: 4852.91 | J33: 4415.7 | K33: 4220.51
A34: Working Capital - Increase/(Decrease) - Cash Flow | B34: -541.16 | C34: -532.98 | D34: 265.53 | E34: 423.67 | F34: -26.82 | G34: 175.09 | H34: -370.66 | I34: 88.23 | J34: 66.24 | K34: 203.29
A35: Accounts Receivables - Decrease/(Increase) - Cash Flow | B35: -341.14 | C35: -17.54 | D35: -380.07 | E35: 200.55 | F35: -172.97 | G35: 359.46 | H35: -321.41 | I35: -50.61 | J35: -14.57 | K35: 235.25
A36: Inventories - Decrease/(Increase) - Cash Flow | B36: -50.69 | C36: -122.79 | D36: -209.56 | E36: 71.45 | F36: -42.91 | G36: -49.08 | H36: 31.1 | I36: -7.79 | J36: 54.32 | K36: -19.18
A37: Prepaid Expenses - Decrease/(Increase) - Cash Flow | B37: -45.21 | C37: -58.02 | D37: -36.45 | E37: 22.56 | F37: 8.05 | G37: 13.26 | H37: -79.06 | I37: 38.93 | J37: 35.77 | K37: -12.79
A38: Other Assets - Decrease/(Increase) - Cash Flow | C38: -294.15
A39: Accounts Payable - Increase/(Decrease) - Cash Flow | B39: 169.88 | C39: -190.25 | D39: 728.91 | E39: 146.65 | F39: -185.04 | G39: -64.99 | H39: 141.27 | I39: 93.43 | J39: -49.02 | K39: -310.69
A40: Accrued Expenses - Increase/(Decrease) - Cash Flow | B40: -204.13 | C40: 94.45 | D40: -9.11 | E40: -36.35 | F40: 387.51 | G40: -55.71 | H40: 47.95 | I40: -46.71 | J40: 119.24 | K40: 43.47
A41: Other Liabilities - Increase/(Decrease) -Total - Cash Flow | B41: -69.87 | C41: 55.32 | D41: 171.81 | E41: 18.8 | F41: -21.45 | G41: -27.85 | H41: -190.51 | I41: 60.99 | J41: -79.49 | K41: 267.22
...

Sheet Balance Sheet
A1: Company Fundamentals - Balance Sheet
A2: Company Name | B2: FirstEnergy Corp (FE.N)
A3: Country of Exchange | B3: United States of America
A4: Country of Headquarters | B4: United States of America
A5: TRBC Industry Group | B5: Electric Utilities & IPPs
A6: CF Template | B6: IND
A7: Consolidation Basis | B7: Consolidated
A8: Scaling | B8: Millions
A9: Period | B9: Annual
A10: Export Date | B10: 45975.878
A11: Statement Data | B11: 2024 | C11: 2023 | D11: 2022 | E11: 2021 | F11: 2020 | G11: 2019 | H11: 2018 | I11: 2017 | J11: 2016 | K11: 2015
A12: Period End Date | B12: 45657 | C12: 45291 | D12: 44926 | E12: 44561 | F12: 44196 | G12: 43830 | H12: 43465 | I12: 43100 | J12: 42735 | K12: 42369
A13: Statement Date | B13: 45656 | C13: 45290 | D13: 44925 | E13: 44560 | F13: 44195 | G13: 43829 | H13: 43464 | I13: 43464 | J13: 42734 | K13: 42734
A14: Standardized Currency | B14: USD | C14: USD | D14: USD | E14: USD | F14: USD | G14: USD | H14: USD | I14: USD | J14: USD | K14: USD
A15: Template Type | B15: Industrial - Differentiated | C15: Industrial - Differentiated | D15: Industrial - Differentiated | E15: Industrial - Differentiated | F15: Industrial - Differentiated | G15: Industrial - Differentiated | H15: Industrial - Differentiated | I15: Industrial - Differentiated | J15: Industrial - Differentiated | K15: Industrial - Differentiated
A16: Period End FX Rate | B16: 1.438 | C16: 1.3245 | D16: 1.3549 | E16: 1.2634 | F16: 1.273 | G16: 1.2986 | H16: 1.3637 | I16: 1.2577 | J16: 1.343 | K16: 1.3839
A17: Avg. FX Rate
A19: Balance Sheet - Standardized (Currency: Canadian Dollar)
A20: Field Name | B20: 30-12-2024 | C20: 30-12-2023 | D20: 30-12-2022 | E20: 30-12-2021 | F20: 30-12-2020 | G20: 30-12-2019 | H20: 30-12-2018 | I20: 30-12-2017 | J20: 30-12-2016 | K20: 30-12-2015
A21: Current Assets
A22: Cash & Short-Term Investments | B22: 159.62 | C22: 181.46 | D22: 216.78 | E22: 1847.09 | F22: 2207.38 | G22: 814.22 | H22: 500.48 | I22: 739.53 | J22: 267.26 | K22: 181.29
A23: Cash & Cash Equivalents | B23: 159.62 | C23: 181.46 | D23: 216.78 | E23: 1847.09 | F23: 2207.38 | G23: 814.22 | H23: 500.48 | I23: 739.53 | J23: 267.26 | K23: 181.29
A24: Derivative Financial Instruments - Hedging - Short-Term | J24: 188.02 | K24: 217.27
A25: Loans & Receivables - Net - Short-Term | B25: 2635.85 | C25: 2098.01 | D25: 2128.55 | E25: 1615.89 | F25: 1831.85 | G25: 1680.39 | H25: 2060.55 | I25: 1826.18 | J25: 2168.95 | K25: 2207.32
A26: Trade Accounts & Trade Notes Receivable - Net | B26: 2200.14 | C26: 1745.69 | D26: 1785.76 | E26: 1305.09 | F26: 1531.42 | G26: 1416.77 | H26: 1692.35 | I26: 1612.37 | J26: 1933.92 | K26: 1958.22
A27: Trade Accounts & Trade Notes Receivable - Gross | B27: 2279.23 | C27: 1830.46 | D27: 1971.38 | E27: 1505.97 | F27: 1740.19 | G27: 2856.92 | H27: 1760.54 | I27: 1674 | J27: 2005.1 | K27: 2053.71
A28: Provision - Trade Accounts & Trade Notes Receivable | B28: 79.09 | C28: 84.77 | D28: 185.62 | E28: 200.88 | F28: 208.77 | G28: 1440.15 | H28: 68.19 | I28: 61.63 | J28: 71.18 | K28: 95.49
A29: Receivables - Other - Total | B29: 435.71 | C29: 352.32 | D29: 342.79 | E29: 310.8 | F29: 300.43 | G29: 263.62 | H29: 368.2 | I29: 213.81 | J29: 235.03 | K29: 249.1
A30: Inventories - Total | B30: 789.46 | C30: 678.14 | D30: 570.41 | E30: 328.48 | F30: 403.54 | G30: 364.91 | H30: 343.65 | I30: 296.82 | J30: 757.45 | K30: 1086.36
A31: Inventories - Raw Materials | B31: 789.46 | C31: 678.14 | D31: 570.41 | E31: 328.48 | F31: 403.54 | G31: 364.91 | H31: 343.65 | I31: 296.82 | J31: 757.45 | K31: 1086.36
A32: Prepaid Expenses - Short-Term | B32: 345.12 | C32: 388.08 | D32: 294.01 | E32: 236.26 | F32: 199.86 | G32: 203.88 | H32: 238.65 | I32: 189.91 | J32: 131.61 | K32: 186.83
A33: Assets Held for Sale/Discontinued Operations - Short-Term | F33: 0 | G33: 42.85 | H33: 34.09 | I33: 794.87
A34: Other Current Assets - Total | B34: 61.83 | C34: 55.63 | D34: 62.33 | E34: 61.91 | F34: 85.29 | G34: 67.53 | H34: 84.55 | I34: 64.14 | J34: 448.56 | K34: 327.98
A35: Restricted Accounts - Short-Term | B35: 61.83 | C35: 55.63 | D35: 62.33 | E35: 61.91 | F35: 85.29 | G35: 67.53 | H35: 84.55 | I35: 64.14
A36: Other Current Assets | J36: 448.56 | K36: 327.98
A37: Total Current Assets | B37: 3991.89 | C37: 3401.32 | D37: 3272.08 | E37: 4089.63 | F37: 4727.92 | G37: 3173.78 | H37: 3261.97 | I37: 3911.45 | J37: 3961.85 | K37: 4207.06
A38: Non-Current Assets
A39: Investments - Long-Term | B39: 937.58 | C39: 878.14 | D39: 842.75 | E39: 827.53 | F39: 770.17 | G39: 738.9 | H39: 694.12 | I39: 636.4 | J39: 687.62 | K39: 700.25
A40: Investments - Available for Sale/Held to Maturity - Long-Term | B40: 937.58 | C40: 878.14 | D40: 842.75 | E40: 827.53 | F40: 770.17 | G40: 738.9 | H40: 694.12 | I40: 636.4 | J40: 687.62 | K40: 700.25
A41: Property, Plant & Equipment - Net - Total | B41: 59432.54 | C41: 51148.22 | D41: 49517.53 | E41: 44248.06 | F41: 42720.61 | G41: 41400.67 | H41: 40789.63 | I41: 35342.63 | J41: 39466.74 | K41: 51500.45
...

Sheet Valuation
A1: Company Fundamentals - Valuation
A2: Company Name | B2: FirstEnergy Corp (FE.N)
A3: Country of Exchange | B3: United States of America
A4: Country of Headquarters | B4: United States of America
A5: TRBC Industry Group | B5: Electric Utilities & IPPs
A6: CF Template | B6: IND
A7: Consolidation Basis | B7: Consolidated
A8: Scaling | B8: Millions
A9: Period | B9: Annual
A10: Export Date | B10: 45975.878
A11: Statement Data | B11: 2024 | C11: 2023 | D11: 2022 | E11: 2021 | F11: 2020 | G11: 2019 | H11: 2018 | I11: 2017 | J11: 2016 | K11: 2015
A12: Period End Date | B12: 45657 | C12: 45291 | D12: 44926 | E12: 44561 | F12: 44196 | G12: 43830 | H12: 43465 | I12: 43100 | J12: 42735 | K12: 42369
A13: Statement Date | B13: 45656 | C13: 45290 | D13: 44925 | E13: 44560 | F13: 44195 | G13: 43829 | H13: 43464 | I13: 43464 | J13: 43464 | K13: 42368
A14: Standardized Currency | B14: USD | C14: USD | D14: USD | E14: USD | F14: USD | G14: USD | H14: USD | I14: USD | J14: USD | K14: USD
A15: Template Type | B15: Industrial - Operating | C15: Industrial - Operating | D15: Industrial - Operating | E15: Industrial - Operating | F15: Industrial - Operating | G15: Industrial - Operating | H15: Industrial - Operating | I15: Industrial - Operating | J15: Industrial - Operating | K15: Industrial - Operating
A16: Period End FX Rate | B16: 1.438 | C16: 1.3245 | D16: 1.3549 | E16: 1.2634 | F16: 1.273 | G16: 1.2986 | H16: 1.3637 | I16: 1.2577 | J16: 1.343 | K16: 1.3839
A17: Avg. FX Rate | B17: 1.370032 | C17: 1.3493112 | D17: 1.3016236 | E17: 1.2534562 | F17: 1.3408481 | G17: 1.3264151 | H17: 1.2960156 | I17: 1.2975704 | J17: 1.3248434 | K17: 1.278554
A19: Valuation - Standardized (Currency: Canadian Dollar)
A20: Field Name | B20: 30-12-2024 | C20: 30-12-2023 | D20: 30-12-2022 | E20: 30-12-2021 | F20: 30-12-2020 | G20: 30-12-2019 | H20: 30-12-2018 | I20: 30-12-2017 | J20: 30-12-2016 | K20: 30-12-2015
A21: Enterprise Value
A22: Enterprise Value | B22: 69171.96 | C22: 61308.52 | D22: 62258.1 | E22: 56896.48 | F22: 50094.7 | G22: 60553.91 | H22: 52383.5 | I22: 40974.04 | J22: 47746.94 | K22: 48804.78
A23: Enterprise Value, 5 Year Average | B23: 64631.59 | C23: 59140.15 | D23: 58363.5 | E23: 51043.27 | F23: 49017.02 | G23: 48941.65 | H23: 49069.36 | I23: 44202.63 | J23: 48240.07 | K23: 49744.77
A24: Market Capitalization
A25: Market Capitalization | B25: 32967.43 | C25: 27862.25 | D25: 32489.59 | E25: 28606.42 | F25: 21142.86 | G25: 34100.13 | H25: 26189.55 | I25: 17131.83 | J25: 17726.86 | K25: 18576.25
A26: Market Capitalization, 5 Year Average | B26: 30828.53 | C26: 29278.24 | D26: 29453.99 | E26: 24847.68 | F26: 22632.31 | G26: 22260.09 | H26: 20688.85 | I26: 17719.49 | J26: 19953.54 | K26: 22035.77
A27: Price Close
A28: Price Close (End of Period) | B28: 57.2 | C28: 48.56 | D28: 56.82 | E28: 52.54 | F28: 38.97 | G28: 63.11 | H28: 51.21 | I28: 38.51 | J28: 41.59 | K28: 43.91
A29: Price Close (End of Period), 5 Year Average | B29: 54.81 | C29: 52.82 | D29: 54.27 | E29: 47.75 | F29: 45.41 | G29: 46.61 | H29: 46.33 | I29: 41.58 | J29: 47.39 | K29: 52.52
A30: FOCF Yield
A31: Free Cash Flow Yield - % | B31: -4.96 | C31: -9.36 | D31: -0.3 | E31: 1.61 | F31: -7.42 | G31: -0.75 | H31: -6.82 | I31: 7.11 | J31: 2.4 | K31: 4.21
A32: Free Cash Flow Yield - %, 5 Year Average | B32: -3.74 | C32: -2.77 | D32: -2.32 | E32: -1.24 | F32: -1.28 | G32: 0.74 | H32: -0.17 | I32: 1.05 | J32: -1.12 | K32: -0.4
A33: Dividend Yield
A34: Dividend Yield - Common Stock - Net - Issue Specific - % | B34: 4.27 | C34: 4.36 | D34: 3.72 | E34: 3.75 | F34: 5.1 | G34: 3.15 | H34: 4.85 | I34: 4.7 | J34: 4.65 | K34: 4.54
A35: Dividend Yield - Common Stock - Net - Issue Specific - %, 5 Year Average | B35: 4.19 | C35: 3.92 | D35: 4.01 | E35: 4.19 | F35: 4.37 | G35: 4.27 | H35: 4.46 | I35: 4.15
A36: Dividend Yield - Common Stock - Gross - Issue Specific - % | B36: 4.27 | C36: 4.36 | D36: 3.72 | E36: 3.75 | F36: 5.1 | G36: 3.15 | H36: 4.85 | I36: 4.7 | J36: 4.65 | K36: 4.54
A37: Dividend Yield - Common Stock - Gross - Issue Specific - %, 5 Year Average | B37: 4.19 | C37: 3.92 | D37: 4.01 | E37: 4.19 | F37: 4.37 | G37: 4.27 | H37: 4.46 | I37: 4.48 | J37: 4.63 | K37: 4.71
A38: Price to Book
A39: Price to Book Value per Share - Issue Specific | B39: 1.84 | C39: 2.02 | D39: 2.36 | E39: 2.73 | F39: 2.3 | G39: 3.77 | H39: 2.85 | I39: 3.47 | J39: 2.2 | K39: 1.08
A40: Price to Book Value per Share - Issue Specific, 5 Year Average | B40: 2.21 | C40: 2.58 | D40: 2.77 | E40: 2.98 | F40: 2.86 | G40: 2.29 | H40: 1.79 | I40: 1.48 | J40: 1.31 | K40: 1.25
A41: Price to Tangible Book
...

Sheet DCF
A1: Revenue Forecast | B1: Historical | N1: Forecast | U1: Cost Forecast | V1: Historical | AH1: Forecast | AO1: CapEx
A2: Year | B2: 2014 | C2: 2015 | D2: 2016 | E2: 2017 | F2: 2018 | G2: 2019 | H2: 2020 | I2: 2021 | J2: 2022 | K2: 2023 | L2: 2024 | M2: Revenue growth by Segement (CAGR) | N2: 2025E | O2: 2026E | P2: 2027E | Q2: 2028E | R2: 2029E | U2: Year | V2: 2014 | W2: 2015 | X2: 2016 | Y2: 2017 | Z2: 2018 | AA2: 2019 | AB2: 2020 | AC2: 2021 | AD2: 2022 | AE2: 2023 | AF2: 2024 | AG2: Cost growth (CAGR) | AH2: 2025E | AI2: 2026E | AJ2: 2027E | AK2: 2028E | AL2: 2029E | AO2: CapEx | AP2: Historical | BA2: Forecast
A3: Utility Revenue - Electric Operations | C3: 13598.7 | D3: 12994.06 | E3: 12965.32 | F3: 13312.67 | G3: 13569.23 | H3: 13812.08 | I3: 13307.94 | J3: 15331.82 | K3: 16804.32 | L3: 17980.3 | M3: =POWER((L3/D3),1/8)-1 -> 0.041433415 | N3: =L3*(1+M3) -> 18725.285 | O3: =N3*(1+M3) -> 19501.138 | P3: =O3*(1+M3) -> 20309.136 | Q3: =P3*(1+M3) -> 21150.613 | R3: =Q3*(1+M3) -> 22026.956 | U3: Cost Items | AN3: 2014 | AO3: Year | AP3: 2015 | AQ3: 2016 | AR3: 2017 | AS3: 2018 | AT3: 2019 | AU3: 2020 | AV3: 2021 | AW3: 2022 | AX3: 2023 | AY3: 2024 | AZ3: Cost growth (CAGR) | BA3: 2025E | BB3: 2026E | BC3: 2027E | BD3: 2028E | BE3: 2029E
A4: Utility Revenue - Non-Utility Operations | C4: 5612.85 | D4: 1181.76 | E4: 1214.53 | F4: 1281.76 | G4: 1067.76 | H4: 655.67 | I4: 645.53 | J4: 885.1 | K4: 561.31 | L4: 476.77 | M4: =POWER((L4/D4),1/8)-1 -> -0.10726522 | N4: =L4*(1+M4) -> 425.62916 | O4: =N4*(1+M4) -> 379.97395 | P4: =O4*(1+M4) -> 339.21596 | Q4: =P4*(1+M4) -> 302.82989 | R4: =Q4*(1+M4) -> 270.34677 | U4: Cost of Operating Revenue | V4: =9073.57 -> 9073.57 | W4: 9531.62 | X4: 6377.8 | Y4: 5774.19 | Z4: 6198.84 | AA4: 6159.87 | AB4: 5824.64 | AC4: 5950.16 | AD4: 7768.09 | AE4: 8240.24 | AF4: 8161.28 | AN4: 3915.02 | AO4: Capital Expenditures - Total | AP4: ='Cash Flow'!K48 -> 3700.14 | AQ4: ='Cash Flow'!J48 -> 4063.29 | AR4: ='Cash Flow'!I48 -> 3686.4 | AS4: ='Cash Flow'!H48 -> 3466.84 | AT4: ='Cash Flow'!G48 -> 3534.9 | AU4: ='Cash Flow'!F48 -> 3562.63 | AV4: ='Cash Flow'!E48 -> 3064.7 | AW4: ='Cash Flow'!D48 -> 3587.27 | AX4: ='Cash Flow'!C48 -> 4528.29 | AY4: ='Cash Flow'!B48 -> 5521.23 | AZ4: 0.035 | BA4: =AY4*50% -> 2760.615 | BB4: =BA4*(1+AZ4) -> 2857.2365 | BC4: =BB4*(1+AZ4) -> 2957.2398 | BD4: =BC4*(1+AZ4) -> 3060.7432 | BE4: =BD4*(1+AZ4) -> 3167.8692
A5: Revenue from Business Activities - Total | C5: 19211.55 | D5: 14175.82 | E5: 14179.85 | F5: 14594.43 | G5: 14636.99 | H5: 14467.75 | I5: 13953.47 | J5: 16216.93 | K5: 17365.64 | L5: 18457.07 | M5: =4.8% -> 0.048 | N5: =L5*(1+M5) -> 19343.009 | O5: =N5*(1+M5) -> 20271.474 | P5: =O5*(1+M5) -> 21244.505 | Q5: =P5*(1+M5) -> 22264.241 | R5: =Q5*(1+M5) -> 23332.924 | U5: Cost of Revenues - Total | V5: =9073.57 -> 9073.57 | W5: 9531.62 | X5: 6377.8 | Y5: 5774.19 | Z5: 6198.84 | AA5: 6159.87 | AB5: 5824.64 | AC5: 5950.16 | AD5: 7768.09 | AE5: 8240.24 | AF5: 8161.28 | AG5: =POWER((AF5/V5),1/10)-1 -> -0.010540532 | AO5: growth rate | AP5: =(AP4-AN4)/AN4 -> -0.054886054 | AQ5: =(AQ4-AP4)/AP4 -> 0.098144935 | AR5: =(AR4-AQ4)/AQ4 -> -0.092754886 | AS5: =(AS4-AR4)/AR4 -> -0.059559462 | AT5: =(AT4-AS4)/AS4 -> 0.019631711 | AU5: =(AU4-AT4)/AT4 -> 0.0078446349 | AV5: =(AV4-AU4)/AU4 -> -0.13976472 | AW5: =(AW4-AV4)/AV4 -> 0.17051261 | AX5: =(AX4-AW4)/AW4 -> 0.26232204 | AY5: =(AY4-AX4)/AX4 -> 0.21927483 | AZ5: =AVERAGE(AP5:AY5) -> 0.043076564
N6: =N3+N4 -> 19150.914 | O6: =O3+O4 -> 19881.112 | P6: =P3+P4 -> 20648.352 | Q6: =Q3+Q4 -> 21453.443 | R6: =R3+R4 -> 22297.302 | U6: Depreciation in Cost of Revenues | V6: 1347.34 | W6: 1639.11 | X6: 1236.08 | Y6: 1332.6 | Z6: 1472.27 | AA6: 1618.23 | AB6: 1708.24 | AC6: 1632 | AD6: 1789.73 | AE6: 1971.34 | AF6: 2166.02 | AG6: =POWER((AF6/V6),1/10)-1 -> 0.04862094 | AH6: =AF6*(1+AG16) -> 2287.4412 | AI6: =AH6*(1+AG16) -> 2415.669 | AJ6: =AI6*(1+AG16) -> 2551.0848 | AK6: =AJ6*(1+AG165) -> 2551.0848 | AL6: =AK6*(1+AG16) -> 2694.0918
A7: Net Working Capital | U7: Material Expenses | V7: 7726.23 | W7: 7892.51 | X7: 5141.72 | Y7: 4441.58 | Z7: 4726.57 | AA7: 4541.65 | AB7: 4116.4 | AC7: 4318.16 | AD7: 5978.36 | AE7: 6268.9 | AF7: 5995.26 | AG7: =POWER((AF7/V7),1/10)-1 -> -0.025046194 | AH7: =AF7*(1+AG9) -> 6012.4549 | AI7: =AH7+(1+AG9) -> 6013.4578 | AJ7: =AI7*(1+AG9) -> 6030.7049 | AK7: =AJ7*(1+AG9) -> 6048.0015 | AL7: =AK7*(1+AG9) -> 6065.3478
B8: Operating CA = AR+Inv+Prepaid+OCA | C8: Operating CL = AP+Acc+OCL | D8: Operating NWC | U8: Utility Cost of Revenue - Fuel Expense | V8: 2517.98 | W8: 2371.72 | X8: 756.49 | Y8: 644.89 | Z8: 697.26 | AA8: 659.23 | AB8: 494.77 | AC8: 602.91 | AD8: 950.19 | AE8: 725.93 | AF8: 635.69 | AG8: =POWER((AF8/V8),1/10)-1 -> -0.12859648
A9: 2015 | B9: 3396.53 | C9: 3518.8 | D9: -122.27 | E9: =D9/C5 -> -0.0063644006 | U9: Utility Cost of Revenue - Purchased Power | V9: 5208.25 | W9: 5520.8 | X9: 4385.23 | Y9: 3796.69 | Z9: 4029.31 | AA9: 3882.42 | AB9: 3621.63 | AC9: 3715.24 | AD9: 5028.17 | AE9: 5542.97 | AF9: 5359.57 | AG9: =POWER((AF9/V9),1/10)-1 -> 0.0028680892
A10: 2016 | B10: 2867.53 | C10: 3151 | D10: -283.47 | E10: =D10/D5 -> -0.019996727 | U10: Selling, General & Administrative Expenses - Total | V10: 1062.41 | W10: 1250.43 | X10: 1209.58 | Y10: 1219.72 | Z10: 1286.94 | AA10: 1402.02 | AB10: 1482.98 | AC10: 1344.96 | AD10: 1469.53 | AE10: 1570.6 | AF10: 1660.48 | AG10: =POWER((AF10/V10),1/10)-1 -> 0.0456688 | AH10: =AF10*(1+AG10) -> 1736.3121 | AI10: =AH10*(1+AG10) -> 1815.6074 | AJ10: =AI10*(1+AG10) -> 1898.524 | AK10: =AJ10*(1+AG10) -> 1985.2273 | AL10: =AK10*(1+AG10) -> 2075.8903
A11: 2017 | B11: 2712.53 | C11: 3479.4 | D11: -766.87 | E11: =D11/E5 -> -0.054081672 | U11: Other Operating Expense/(Income) - Net | V11: 4318.12 | W11: 5229.29 | X11: 3810.25 | Y11: 3982.24 | Z11: 3866.01 | AA11: 3745.8 | AB11: 4261.22 | AC11: 4631.52 | AD11: 4493.2 | AE11: 4497.25 | AF11: 5381.49 | AG11: =POWER((AF11/V11),1/10)-1 -> 0.022258624 | AH11: =AF11*(1+AG11) -> 5501.2746 | AI11: =AH11*(1+AG11) -> 5623.7254 | AJ11: =AI11*(1+AG11) -> 5748.9018 | AK11: =AJ11*(1+AG11) -> 5876.8644 | AL11: =AK11*(1+AG11) -> 6007.6753
A12: 2018 | B12: 1931.81 | C12: 2403 | D12: -471.19 | E12: =D12/F5 -> -0.032285605 | U12: Operating Expenses - Total | V12: 14454.1 | W12: =W5+W10+W11 -> 16011.34 | X12: =X5+X10+X11 -> 11397.63 | Y12: =Y5+Y10+Y11 -> 10976.15 | Z12: =Z5+Z10+Z11 -> 11351.79 | AA12: =AA5+AA10+AA11 -> 11307.69 | AB12: =AB5+AB10+AB11 -> 11568.84 | AC12: =AC5+AC10+AC11 -> 11926.64 | AD12: =AD5+AD10+AD11 -> 13730.82 | ... AF12: =AF5+AF10+AF11 -> 15203.25 | AH12: =SUM(AH6:AH11) -> 15537.483 | AI12: =SUM(AI6:AI11) -> 15868.46 | AJ12: =SUM(AJ6:AJ11) -> 16229.216 | AK12: =SUM(AK6:AK11) -> 16461.178 | AL12: =SUM(AL6:AL11) -> 16843.005
A13: 2019 | B13: 2220.09 | C13: 2515.5 | D13: -295.41 | E13: =D13/G5 -> -0.020182428 | U13: Growth rote
A14: 2020 | B14: 2053.13 | C14: 3772.5 | D14: -1719.37 | E14: =D14/H5 -> -0.11884156 | U14: Cost of Operating Revenue | W14: =(W4-V4)/V4 -> 0.050481784 | X14: =(X4-W4)/W4 -> -0.33087975 | Y14: =(Y4-X4)/X4 -> -0.094642353 | Z14: =(Z4-Y4)/Y4 -> 0.073542783 | AA14: =(AA4-Z4)/Z4 -> -0.0062866601 | AB14: =(AB4-AA4)/AA4 -> -0.054421603 | AC14: =(AC4-AB4)/AB4 -> 0.02154983 | AD14: =(AD4-AC4)/AC4 -> 0.30552624 | ... AF14: =(AF4-AE4)/AE4 -> -0.0095822452 | AG14: =AVERAGE(W14:AF14) -> 0.0016068734
A15: 2021 | B15: 2359.35 | C15: 3202 | D15: -842.65 | E15: =D15/I5 -> -0.060389996 | U15: Cost of Revenues - Total | W15: =(W5-V5)/V5 -> 0.050481784 | X15: =(X5-W5)/W5 -> -0.33087975 | Y15: =(Y5-X5)/X5 -> -0.094642353 | Z15: =(Z5-Y5)/Y5 -> 0.073542783 | AA15: =(AA5-Z5)/Z5 -> -0.0062866601 | AB15: =(AB5-AA5)/AA5 -> -0.054421603 | AC15: =(AC5-AB5)/AB5 -> 0.02154983 | AD15: =(AD5-AC5)/AC5 -> 0.30552624 | ... AF15: =(AF5-AE5)/AE5 -> -0.0095822452 | AG15: =AVERAGE(W15:AF15) -> 0.0016068734
A16: 2022 | B16: 2163.24 | C16: 2193.4 | D16: -30.16 | E16: =D16/I5 -> -0.0021614695 | U16: Depreciation in Cost of Revenues | W16: =(W6-V6)/V6 -> 0.21655261 | X16: =(X6-W6)/W6 -> -0.24588344 | Y16: =(Y6-X6)/X6 -> 0.078085561 | Z16: =(Z6-Y6)/Y6 -> 0.10481015 | AA16: =(AA6-Z6)/Z6 -> 0.099139424 | AB16: =(AB6-AA6)/AA6 -> 0.055622501 | AC16: =(AC6-AB6)/AB6 -> -0.044630731 | AD16: =(AD6-AC6)/AC6 -> 0.096648284 | ... AF16: =(AF6-AE6)/AE6 -> 0.098755161 | AG16: =AVERAGE(W16:AF16) -> 0.056057293
A17: 2023 | B17: 3271.6 | C17: 2831.1 | D17: 440.5 | E17: =D17/J5 -> 0.027162971 | U17: Material Expenses | W17: =(W7-V7)/V7 -> 0.021521492 | X17: =(X7-W7)/W7 -> -0.34853171 | Y17: =(Y7-X7)/X7 -> -0.13616844 | Z17: =(Z7-Y7)/Y7 -> 0.064164104 | AA17: =(AA7-Z7)/Z7 -> -0.039123508 | AB17: =(AB7-AA7)/AA7 -> -0.093633371 | AC17: =(AC7-AB7)/AB7 -> 0.049013701 | AD17: =(AD7-AC7)/AC7 -> 0.38446931 | ... AF17: =(AF7-AE7)/AE7 -> -0.043650401 | AG17: =AVERAGE(W17:AF17) -> -0.0093340211
A18: 2024 | B18: 3559.4 | C18: 2910.3 | D18: 649.1 | E18: =D18/L5 -> 0.035168095 | U18: Utility Cost of Revenue - Fuel Expense | W18: =(W8-V8)/V8 -> -0.058086244 | X18: =(X8-W8)/W8 -> -0.68103739 | Y18: =(Y8-X8)/X8 -> -0.14752343 | Z18: =(Z8-Y8)/Y8 -> 0.081207648 | AA18: =(AA8-Z8)/Z8 -> -0.054542065 | AB18: =(AB8-AA8)/AA8 -> -0.24947287 | AC18: =(AC8-AB8)/AB8 -> 0.2185662 | AD18: =(AD8-AC8)/AC8 -> 0.57600637 | ... AF18: =(AF8-AE8)/AE8 -> -0.12430951 | AG18: =AVERAGE(W18:AF18) -> -0.067520724
B19: Revenue | C19: Operating NWC (3% of Rev) | U19: Utility Cost of Revenue - Purchased Power | W19: =(W9-V9)/V9 -> 0.06001056 | X19: =(X9-W9)/W9 -> -0.20568939 | Y19: =(Y9-X9)/X9 -> -0.13420961 | Z19: =(Z9-Y9)/Y9 -> 0.061269158 | AA19: =(AA9-Z9)/Z9 -> -0.036455373 | AB19: =(AB9-AA9)/AA9 -> -0.067172022 | AC19: =(AC9-AB9)/AB9 -> 0.025847478 | AD19: =(AD9-AC9)/AC9 -> 0.35339036 | ... AF19: =(AF9-AE9)/AE9 -> -0.033086955 | AG19: =AVERAGE(W19:AF19) -> 0.012628738
A20: 2025 | B20: =N5 -> 19343.009 | C20: =B20*0.01 -> 193.43009 | U20: Selling, General & Administrative Expenses - Total | W20: =(W10-V10)/V10 -> 0.17697499 | X20: =(X10-W10)/W10 -> -0.032668762 | Y20: =(Y10-X10)/X10 -> 0.0083830751 | Z20: =(Z10-Y10)/Y10 -> 0.055111009 | AA20: =(AA10-Z10)/Z10 -> 0.089421418 | AB20: =(AB10-AA10)/AA10 -> 0.057745253 | AC20: =(AC10-AB10)/AB10 -> -0.09306936 | AD20: =(AD10-AC10)/AC10 -> 0.092619855 | ... AF20: =(AF10-AE10)/AE10 -> 0.057226538 | AG20: =AVERAGE(W20:AF20) -> 0.048052111
A21: 2026 | B21: =O5 -> 20271.474 | C21: =B21*0.01 -> 202.71474 | U21: Other Operating Expense/(Income) - Net | W21: =(W11-V11)/V11 -> 0.21101081 | X21: =(X11-W11)/W11 -> -0.2713638 | Y21: =(Y11-X11)/X11 -> 0.04513877 | Z21: =(Z11-Y11)/Y11 -> -0.029187091 | AA21: =(AA11-Z11)/Z11 -> -0.031094074 | AB21: =(AB11-AA11)/AA11 -> 0.13759944 | AC21: =(AC11-AB11)/AB11 -> 0.086899996 | AD21: =(AD11-AC11)/AC11 -> -0.029864926 | ... AF21: =(AF11-AE11)/AE11 -> 0.19661793 | AG21: =AVERAGE(W21:AF21) -> 0.031665843
A22: 2027 | B22: =P5 -> 21244.505 | C22: =B22*0.01 -> 212.44505 | U22: Operating Expenses - Total | W22: =(W12-V12)/V12 -> 0.10773691 | X22: =(X12-W12)/W12 -> -0.28815265 | Y22: =(Y12-X12)/X12 -> -0.036979618 | Z22: =(Z12-Y12)/Y12 -> 0.034223293 | AA22: =(AA12-Z12)/Z12 -> -0.0038848499 | AB22: =(AB12-AA12)/AA12 -> 0.023094903 | AC22: =(AC12-AB12)/AB12 -> 0.030927906 | AD22: =(AD12-AC12)/AC12 -> 0.15127312 | ... AF22: =(AF12-AE12)/AE12 -> 0.062563207 | AG22: =AVERAGE(W22:AF22) -> 0.012284413
A23: 2028 | B23: =Q5 -> 22264.241 | C23: =B23*0.01 -> 222.64241
A24: 2029 | B24: =R5 -> 23332.924 | C24: =B24*0.01 -> 233.32924 | AO24: WACC
AP25: Total Value of Equity | AS25: Total Value of Preference Shares | AV25: Total Value of Debt
V26: Forecast | AO26: Share Price | AP26: 45.94 | AS26: 0 | AV26: 27470
V27: 2025E | W27: 2026E | X27: 2027E | Y27: 2028E | Z27: 2029E | AA27: 2018 | AB27: 2019 | AC27: 2020 | AD27: 2021 | AE27: 2022 | AF27: 2023 | AG27: 2024 | AH27: 2025E | AI27: 2026E | AJ27: 2027E | AK27: 2028E | AL27: 2029E | AO27: Outstanding Shares | AP27: 577.67 | AS27: 0
U28: Total Revenue | V28: =N5 -> 19343.009 | W28: =O5 -> 20271.474 | X28: =P5 -> 21244.505 | Y28: =Q5 -> 22264.241 | Z28: =R5 -> 23332.924 | AA28: =F5 -> 14594.43 | AB28: =G5 -> 14636.99 | AC28: =H5 -> 14467.75 | AD28: =I5 -> 13953.47 | AE28: =J5 -> 16216.93 | AF28: =K5 -> 17365.64 | AG28: =L5 -> 18457.07 | AO28: TVE | AP28: =AP26*AP27 -> 26538.16 | AR28: TVP | AS28: =AS26*AS27 -> 0 | AU28: TVD | AV28: =AV26 -> 27470
U29: Revenue growth | V29: =(N5-L5)/L5 -> 0.048 | W29: =(W28-V28)/V28 -> 0.048 | X29: =(X28-W28)/W28 -> 0.048 | Y29: =(Y28-X28)/X28 -> 0.048 | Z29: =(Z28-Y28)/Y28 -> 0.048 | AO29: Total Market Value | AQ29: =AP28+AV28 -> 54008.16
U30: Total Expenses of Operating | V30: =AH12 -> 15537.483 | W30: =AI12 -> 15868.46 | X30: =AJ12 -> 16229.216 | Y30: =AK12 -> 16461.178 | Z30: =AL12 -> 16843.005 | AA30: =Z12 -> 11351.79 | AB30: =AA12 -> 11307.69 | AC30: =AB12 -> 11568.84 | AD30: =AC12 -> 11926.64 | AE30: =AD12 -> 13730.82 | AF30: =AE12 -> 14308.09 | AG30: =AF12 -> 15203.25 | AO30: Cost of Equity | AQ30: =DDM!F18 -> 0.0692475
U31: Depreciation and amortization | V31: =AH6 -> 2287.4412 | W31: =AI6 -> 2415.669 | X31: =AJ6 -> 2551.0848 | Y31: =AK6 -> 2551.0848 | Z31: =AL6 -> 2694.0918 | AA31: =Z6 -> 1472.27 | AB31: =AA6 -> 1618.23 | AC31: =AB6 -> 1708.24 | AD31: =AC6 -> 1632 | AE31: =AD6 -> 1789.73 | AF31: =AE6 -> 1971.34 | AG31: =AF6 -> 2166.02 | AO31: Cost of Debt | AQ31: =AQ32/AQ33*(1-AQ34) -> 0.036886333
U32: EBITDA | V32: =V34+V31 -> 3805.5265 | W32: =W34+W31 -> 4403.0142 | X32: =X34+X31 -> 5015.289 | Y32: =Y34+Y31 -> 5803.0626 | Z32: =Z34+Z31 -> 6489.9192 | AA32: =AA34+AA31 -> 3242.64 | AB32: =AB34+AB31 -> 3329.3 | AC32: =AC34+AC31 -> 2898.91 | ... AG32: =AG34+AG31 -> 3253.82 | AO32: Interest Expenses | AQ32: ='Income Statement'!B47 -> 1352.22
U33: EBITDA Margin | V33: =V32/V28 -> 0.19673911 | W33: =W32/W28 -> 0.21720247 | X33: =X32/X28 -> 0.23607465 | Y33: =Y32/Y28 -> 0.26064498 | Z33: =Z32/Z28 -> 0.27814427 | AO33: Value of Debt | AQ33: =AV28 -> 27470
U34: EBIT | V34: =V28-V30-V31 -> 1518.0853 | W34: =W28-W30-W31 -> 1987.3453 | X34: =X28-X30-X31 -> 2464.2041 | Y34: =Y28-Y30-Y31 -> 3251.9778 | Z34: =Z28-Z30-Z31 -> 3795.8275 | AA34: =AA28-AA30-AA31 -> 1770.37 | AB34: =AB28-AB30-AB31 -> 1711.07 | AC34: =AC28-AC30-AC31 -> 1190.67 | ... AG34: =AG28-AG30-AG31 -> 1087.8 | AO34: Effective Tax Rate | AQ34: =AQ35/AQ36 -> 0.25066366
U35: EBIT Margin | V35: =V34/V28 -> 0.078482374 | W35: =W34/W28 -> 0.098036545 | X35: =X34/X28 -> 0.11599254 | Y35: =Y34/Y28 -> 0.14606282 | Z35: =Z34/Z28 -> 0.16268117 | AO35: Tax Expense | AQ35: ='Income Statement'!B69 -> 516.5
U36: Effective Tax Rate | V36: =AQ34 -> 0.25066366 | W36: =V36 -> 0.25066366 | X36: =W36 -> 0.25066366 | Y36: =X36 -> 0.25066366 | Z36: =Y36 -> 0.25066366 | AO36: Pre-Tax Income | AQ36: ='Income Statement'!B67 -> 2060.53
B37: 2015 | C37: 2016 | D37: 2017 | E37: 2018 | F37: 2019 | G37: 2020 | H37: 2021 | I37: 2022 | J37: 2023 | K37: 2024 | L37: 2025E | M37: 2026E | N37: 2027E | O37: 2028E | P37: 2029E | U37: EBIT*(1-Tax Rate) | V37: =V34*(1-V36) -> 1137.5565 | W37: =W34*(1-W36) -> 1489.19 | X37: =X34*(1-X36) -> 1846.5177 | Y37: =Y34*(1-Y36) -> 2436.8251 | Z37: =Z34*(1-Z36) -> 2844.3514 | AA37: =AA34*(1-$Z$36) -> 1326.6026 | AB37: =AB34*(1-$Z$36) -> 1282.1669 | AC37: =AC34*(1-$Z$36) -> 892.21229 | AD37: =AD34*(1-$Z$36) -> 295.86047 | AE37: =AE34*(1-$Z$36) -> 521.82284 | AF37: =AF34*(1-$Z$36) -> 813.93662 | AG37: =AG34*(1-$Z$36) -> 815.12807 | AO37: Cost of Preference Shares | AQ37: 0
B38: 19211.55 | C38: 14175.82 | D38: 14179.85 | E38: 14594.43 | F38: 14636.99 | G38: 14467.75 | H38: 13953.47 | I38: 16216.93 | J38: 17365.64 | K38: 18457.07 | L38: 19343 | M38: 20271 | N38: 21244 | O38: 22264 | P38: 23332 | U38: (Plus)D&A | V38: =V31 -> 2287.4412 | W38: =W31 -> 2415.669 | X38: =X31 -> 2551.0848 | Y38: =Y31 -> 2551.0848 | Z38: =Z31 -> 2694.0918 | AA38: =AA31 -> 1472.27 | AB38: =AB31 -> 1618.23 | AC38: =AC31 -> 1708.24 | ... AG38: =AG31 -> 2166.02 | AO38: DPS for PS
U39: (less)changes in working capital | V39: =C20 -> 193.43009 | W39: =C21 -> 202.71474 | X39: =C22 -> 212.44505 | Y39: =C23 -> 222.64241 | Z39: =C24 -> 233.32924 | AA39: =D12 -> -471.19 | AB39: =D13 -> -295.41 | AC39: =D14 -> -1719.37 | AD39: =D15 -> -842.65 | AE39: =D16 -> -30.16 | AF39: =D17 -> 440.5 | AG39: =D18 -> 649.1
U40: (less)Capex | V40: =BA4 -> 2760.615 | W40: =BB4 -> 2857.2365 | X40: =BC4 -> 2957.2398 | Y40: =BD4 -> 3060.7432 | Z40: =BE4 -> 3167.8692 | AA40: =AS4 -> 3466.84 | AB40: =AT4 -> 3534.9 | AC40: =AU4 -> 3562.63 | AD40: =AV4 -> 3064.7 | AE40: =AW4 -> 3587.27 | AF40: =AX4 -> 4528.29 | AG40: =AY4 -> 5521.23
...

Sheet DDM
A1: Year | B1: Total Dividends | C1: Growth Rate | E1: Growth Rate | H1: Dividend at end of 2025 | I1: =B15 -> 1.78 | J1: =B14*(1+$C$17) -> 1.760825 | K1: =1/(1+$F$18)^1 -> 0.93523716 | L1: =J1*K1 -> 1.646789 | M1: 2025
A2: 2025(Est) | B2: =J1 -> 1.760825 | C2: =POWER((B15/B5),1/10)-1 -> 0.021423278 | E2: Stage 1 growth rate (2025–2029) | F2: =D9 -> 0.026666526 | H2: Dividend at end of 2026 | I2: =I1*(1+F2) -> 1.8274664 | J2: =J1*(1+$C$17) -> 1.8400621 | K2: =1/(1+$F$18)^2 -> 0.87466855 | L2: =J2*K2 -> 1.6094445 | M2: 2026
A3: year | B3: Dividend | E3: Stage 2 growth rate (beyond 2029) | F3: 0.025 | H3: Dividend at end of 2027 | I3: =I2*(1+F2) -> 1.8761986 | J3: =J2*(1+$C$17) -> 1.9228649 | K3: =1/(1+$F$18)^3 -> 0.81802254 | L3: =J3*K3 -> 1.5729468 | M3: 2027
A4: 2014 | B4: 1.44 | H4: Dividend at end of 2028 | I4: =I3*(1+F2) -> 1.9262303 | J4: =J3*(1+$C$17) -> 2.0093938 | K4: =1/(1+$F$18)^4 -> 0.76504508 | L4: =J4*K4 -> 1.5372769 | M4: 2028
A5: 2015 | B5: 1.44 | C5: =(B5-B4)/B4 -> 0 | H5: Dividend at end of 2029 | I5: =I4*(1+F2) -> 1.9775962 | J5: =J4*(1+$C$17) -> 2.0998166 | K5: =1/(1+$F$18)^5 -> 0.71549859 | L5: =J5*K5 -> 1.5024158 | M5: 2029
A6: 2016 | B6: 1.44 | C6: =(B6-B5)/B5 -> 0 | E6: Risk-free Rate | H6: Terminal Value (TV) at Year 2028
A7: 2017 | B7: 1.44 | C7: =(B7-B6)/B6 -> 0 | E7: 10 YEAR CAD BOND | F7: 0.0336 | H7: D2029/(Re-g2) | I7: =I5/(F18-F3) -> 44.693964 | J7: =J5*(1+F3)/(F18-F3) -> 48.642567 | K7: =1/(1+$F$18)^5 -> 0.71549859 | L7: =J7*K7 -> 34.803688
A8: 2018 | B8: 1.44 | C8: =(B8-B7)/B7 -> 0 | H8: Price 2025 | I8: =NPV(F18,I1,I2,I3,I4+I7) -> 40.464472 | J8: =NPV(F18,J1,J2,J3,J4+J7) -> 43.580214 | L8: =SUM(L1:L7) -> 42.672561
A9: 2019 | B9: 1.52 | C9: =(B9-B8)/B8 -> 0.055555556 | D9: =POWER((B15/B9),1/6)-1 -> 0.026666526 | E9: Market Return : Rm
A10: 2020 | B10: 1.56 | C10: =(B10-B9)/B9 -> 0.026315789 | E10: 30 Year Annualized S&P 500 Return (Dividends Reinvested) | F10: 0.1092
A11: 2021 | B11: 1.56 | C11: =(B11-B10)/B10 -> 0 | E11: 20 Year Annualized S&P 500 Return (Dividends Reinvested) | F11: 0.1035
A12: 2022 | B12: 1.56 | C12: =(B12-B11)/B11 -> 0 | E12: Rm average | F12: =AVERAGE(F10:F11) -> 0.10635
A13: 2023 | B13: 1.58 | C13: =(B13-B12)/B12 -> 0.012820513
A14: 2024 | B14: 1.685 | C14: =(B14-B13)/B13 -> 0.066455696 | E14: Beta
A15: 2025 | B15: 1.78 | C15: =(B15-B14)/B14 -> 0.056379822 | E15: 0.49
C16: =(D9+C2)/2 -> 0.024044902
C17: 0.045 | E17: Discount Raate
E18: CAPM : Re = Rf + B (Rm-Rf) | F18: =F7+E15*(F12-F7) -> 0.0692475

Sheet CCA
A1: Company Name | C1: EV / EBITDA | D1: Price / EPS | E1: Price / Cash Flow Per Share
A2: FirstEnergy Corp | C2: 10.94 | D2: 16.96 | E2: 7.87
A3: American Electric Power Company Inc | C3: 11.6 | D3: 19.26 | E3: 9.55
A4: Nextera Energy Inc | C4: 14.87 | D4: 21.13 | E4: 11.41
A5: Southern Co | C5: 12.18 | D5: 19.84 | E5: 9.48
A6: Duke Energy Corp | C6: 11.34 | D6: 18.3 | E6: 8.2
A7: Public Service Enterprise Group Inc | C7: 13.08 | D7: 18.81 | E7: 10.8
A8: Dominion Energy Inc | C8: 12.56 | D8: 16.87 | E8: 9.27
A10: Average | C10: =AVERAGE(C3:C8) -> 12.605 | D10: =AVERAGE(D3:D8) -> 19.035 | E10: =AVERAGE(E3:E8) -> 9.785
C11: =C10*B16 -> 68438.091 | D11: =D10*B17 -> 44.1612 | E11: =E10*B20 -> 67.21477
C12: =C11-34385-1819+159.6 -> 32393.691
C13: =C12/576.6 -> 56.180526
C14: =C13*0.5+D11*0.3+E11*0.2 -> 54.781577
B15: 30-12-2024 | C15: 30-12-2023 | D15: 30-12-2022 | E15: 30-12-2021 | F15: 30-12-2020 | G15: 30-12-2019 | H15: 30-12-2018 | I15: 30-12-2017 | J15: 30-12-2016 | K15: 30-12-2015
A16: Earnings before Interest, Taxes, Depreciation & Amortization (EBITDA) | B16: 5429.44 | C16: 5028.88 | D16: 4275.83 | E16: 4033.62 | F16: 4607.15 | G16: 4947.53 | H16: 4725.27 | I16: 4536.31 | J16: 4014.28 | K16: 5726.64
A17: EPS - Diluted - including Extraordinary Items Applicable to Common - Total | B17: 2.32 | C17: 2.59 | D17: 0.92 | E17: 2.95 | F17: 2.66 | G17: 2.22 | H17: 2.57 | I17: -5.04 | J17: -19.21 | K17: 1.74
A18: Net Cash Flow from Operating Activities | B18: 3960.76 | C18: 1871.49 | D18: 3492.26 | E18: 3523.47 | F18: 1908.03 | G18: 3272.27 | H18: 1827.38 | I18: 4941.15 | J18: 4481.95 | K18: 4423.8
B19: 576.6
B20: =B18/B19 -> 6.8691641

Sheet Ratio
B1: 2024 | C1: 2023 | D1: 2022 | E1: 2021 | F1: 2020 | G1: 2019 | H1: 2018 | I1: 2017
A2: Cash Ratio | B2: ='Balance Sheet'!B23/'Balance Sheet'!B90 -> 0.022213594 | C2: ='Balance Sheet'!C23/'Balance Sheet'!C90 -> 0.025436796 | D2: ='Balance Sheet'!D23/'Balance Sheet'!D90 -> 0.040423743 | E2: ='Balance Sheet'!E23/'Balance Sheet'!E90 -> 0.33106896 | F2: ='Balance Sheet'!F23/'Balance Sheet'!F90 -> 0.34652258 | G2: ='Balance Sheet'!G23/'Balance Sheet'!G90 -> 0.12895899 | H2: ='Balance Sheet'!H23/'Balance Sheet'!H90 -> 0.079197517 | I2: ='Balance Sheet'!I23/'Balance Sheet'!I90 -> 0.14296181
A3: DE | B3: ='Balance Sheet'!B109/'Balance Sheet'!B128 -> 2.7932944 | C3: ='Balance Sheet'!C109/'Balance Sheet'!C128 -> 3.4674794 | D3: ='Balance Sheet'!D109/'Balance Sheet'!D128 -> 3.3322374 | E3: ='Balance Sheet'!E109/'Balance Sheet'!E128 -> 4.2371159 | F3: ='Balance Sheet'!F109/'Balance Sheet'!F128 -> 5.1439828 | G3: ='Balance Sheet'!G109/'Balance Sheet'!G128 -> 5.0646563 | H3: ='Balance Sheet'!H109/'Balance Sheet'!H128 -> 4.8795136 | I3: ='Balance Sheet'!I109/'Balance Sheet'!I128 -> 9.7661203 | M3: FE History Yearly 10 Years
A4: DA | B4: ='Balance Sheet'!B109/'Balance Sheet'!B72 -> 0.7363769 | C4: ='Balance Sheet'!C109/'Balance Sheet'!C72 -> 0.77616013 | D4: ='Balance Sheet'!D109/'Balance Sheet'!D72 -> 0.76917239 | E4: ='Balance Sheet'!E109/'Balance Sheet'!E72 -> 0.80905521 | F4: ='Balance Sheet'!F109/'Balance Sheet'!F72 -> 0.83723913 | G4: ='Balance Sheet'!G109/'Balance Sheet'!G72 -> 0.83511019 | H4: ='Balance Sheet'!H109/'Balance Sheet'!H72 -> 0.8299179 | I4: ='Balance Sheet'!I109/'Balance Sheet'!I72 -> 0.90711603 | M4: Exchange Date | N4: Close | Q4: 20.09 | R4: 0.1248 | S4: 0.0298 | T4: 0.0964 | U4: 7.11 | V4: 0.0849 | W4: 0.6749 | X4: 0.0486 | Y4: 5.74
M5: 46022 | N5: 47.72
A6: Price Earning Ratio | B6: =N6/B7 -> 17.071177 | C6: =N7/C7 -> 14.12712 | D6: =N7/D7 -> 39.611059 | E6: =N8/E7 -> 14.213148 | F6: =N10/F7 -> 11.467272 | G6: =N11/G7 -> 21.588701 | H6: =N12/H7 -> 14.531025 | I6: =N13/I7 -> -6.0774337 | M6: 45657 | N6: 39.78
A7: EPS | B7: ='Income Statement'!B94/'Income Statement'!B114 -> 2.3302435 | C7: ='Income Statement'!C94/'Income Statement'!C114 -> 2.5950087 | D7: ='Income Statement'!D94/'Income Statement'!D114 -> 0.92549912 | E7: ='Income Statement'!E94/'Income Statement'!E114 -> 2.950789 | F7: ='Income Statement'!F94/'Income Statement'!F114 -> 2.6693358 | G7: ='Income Statement'!G94/'Income Statement'!G114 -> 2.2511776 | H7: ='Income Statement'!H94/'Income Statement'!H114 -> 2.584126 | I7: ='Income Statement'!I94/'Income Statement'!I114 -> -5.0383108 | M7: 45291 | N7: 36.66
A8: Price to Book | B8: 1.84 | C8: 2.02 | D8: 2.36 | E8: 2.73 | F8: 2.3 | G8: 3.77 | H8: 2.85 | I8: 3.47 | M8: 44926 | N8: 41.94
A9: Dividend Yield (%) | B9: 4.27 | C9: 4.36 | D9: 3.72 | E9: 3.75 | F9: 5.1 | G9: 3.15 | H9: 4.85 | I9: 4.7 | M9: 44561 | N9: 41.59
M10: 44196 | N10: 30.61
M11: 43830 | N11: 48.6
B12: INCOME STATEMENT -COMMON SIZING | M12: 43465 | N12: 37.55
M13: 43100 | N13: 30.62
A14: Cost of Sales | B14: ='Income Statement'!B29/'Income Statement'!B26 -> 0.44217636 | C14: ='Income Statement'!C29/'Income Statement'!C26 -> 0.47451404 | D14: ='Income Statement'!D29/'Income Statement'!D26 -> 0.47901113 | E14: ='Income Statement'!E29/'Income Statement'!E26 -> 0.42642869 | F14: ='Income Statement'!F29/'Income Statement'!F26 -> 0.40259474 | G14: ='Income Statement'!G29/'Income Statement'!G26 -> 0.42084267 | H14: ='Income Statement'!H29/'Income Statement'!H26 -> 0.42474012 | I14: ='Income Statement'!I29/'Income Statement'!I26 -> 0.40721094 | M14: 42735 | N14: 30.97 | R14: 2024 | S14: 2023 | T14: 2022 | U14: 2021 | V14: 2020 | W14: 2019 | X14: 2018 | Y14: 2017 | AD14: 2024 | AE14: 2023 | AF14: 2022 | AG14: 2021 | AH14: 2020 | AI14: 2019 | AJ14: 2018 | AK14: 2017
A15: Gross Profit | B15: ='Income Statement'!B34/'Income Statement'!B26 -> 0.55782364 | C15: ='Income Statement'!C34/'Income Statement'!C26 -> 0.52548538 | D15: ='Income Statement'!D34/'Income Statement'!D26 -> 0.52098887 | E15: ='Income Statement'!E34/'Income Statement'!E26 -> 0.57357202 | F15: ='Income Statement'!F34/'Income Statement'!F26 -> 0.59740526 | G15: ='Income Statement'!G34/'Income Statement'!G26 -> 0.57915733 | H15: ='Income Statement'!H34/'Income Statement'!H26 -> 0.57525988 | I15: ='Income Statement'!I34/'Income Statement'!I26 -> 0.59278906 | M15: 42369 | N15: 31.73 | Q15: Net Margin - % | R15: 0.23 | S15: 0.223 | T15: 0.155 | U15: 0.166 | V15: 0.139 | W15: 0.189 | X15: 0.327 | Y15: 0.206 | AB15: Net Margin - % | AC15: IND | AD15: 0.152 | AE15: 0.15 | AF15: 0.117 | AG15: 0.148 | AH15: 0.139 | AI15: 0.143 | AJ15: 0.119 | AK15: 0.123
A16: Total Expenses | B16: ='Income Statement'!B42/'Income Statement'!B26 -> 0.82370821 | C16: ='Income Statement'!C42/'Income Statement'!C26 -> 0.82393163 | D16: ='Income Statement'!D42/'Income Statement'!D26 -> 0.84669725 | E16: ='Income Statement'!E42/'Income Statement'!E26 -> 0.85474366 | F16: ='Income Statement'!F42/'Income Statement'!F26 -> 0.79962952 | G16: ='Income Statement'!G42/'Income Statement'!G26 -> 0.77254203 | H16: ='Income Statement'!H42/'Income Statement'!H26 -> 0.77781729 | I16: ='Income Statement'!I42/'Income Statement'!I26 -> 0.77406672 | Q16: Return on Average Total Assets | R16: 0.031 | S16: 0.037 | T16: 0.022 | U16: 0.021 | V16: 0.02 | W16: 0.031 | X16: 0.053 | Y16: 0.037 | AC16: FE | AD16: 0.084 | AE16: 0.093 | AF16: 0.035 | AG16: 0.111 | AH16: 0.093 | AI16: 0.082 | AJ16: 0.093 | AK16: 0.083
A17: Interest Expenses | B17: ='Income Statement'!B47/'Income Statement'!B26 -> 0.073262983 | C17: ='Income Statement'!C47/'Income Statement'!C26 -> 0.079797808 | D17: ='Income Statement'!D47/'Income Statement'!D26 -> 0.076651376 | E17: ='Income Statement'!E47/'Income Statement'!E26 -> 0.095759693 | F17: ='Income Statement'!F47/'Income Statement'!F26 -> 0.091566415 | G17: ='Income Statement'!G47/'Income Statement'!G26 -> 0.087177077 | H17: ='Income Statement'!H47/'Income Statement'!H26 -> 0.093330812 | I17: ='Income Statement'!I47/'Income Statement'!I26 -> 0.087206846 | Q17: Total Debt Percentage of Total Equity | R17: 1.677 | S17: 1.705 | T17: 1.693 | U17: 1.609 | V17: 1.625 | W17: 1.492 | X17: 1.318 | Y17: 1.245 | AB17: Return on Average Total Assets | AC17: IND | AD17: 0.03 | AE17: 0.024 | AF17: 0.022 | AG17: 0.02 | AH17: 0.02 | AI17: 0.027 | AJ17: 0.028 | AK17: 0.03
A18: Operating Profit | B18: ='Income Statement'!B44/'Income Statement'!B26 -> 0.17629179 | C18: ='Income Statement'!C44/'Income Statement'!C26 -> 0.17606837 | D18: ='Income Statement'!D44/'Income Statement'!D26 -> 0.15330275 | E18: ='Income Statement'!E44/'Income Statement'!E26 -> 0.14525706 | F18: ='Income Statement'!F44/'Income Statement'!F26 -> 0.20037048 | G18: ='Income Statement'!G44/'Income Statement'!G26 -> 0.22745797 | H18: ='Income Statement'!H44/'Income Statement'!H26 -> 0.22218271 | I18: ='Income Statement'!I44/'Income Statement'!I26 -> 0.22593328 | Q18: Asset Turnover | R18: 0.2 | S18: 0.2 | T18: 0.22 | V18: 0.19 | W18: 0.22 | X18: 0.24 | Y18: 0.24 | AC18: FE | AD18: 0.022 | AE18: 0.025 | AF18: 0.01 | AG18: 0.028 | AH18: 0.023 | AI18: 0.022 | AJ18: 0.025 | AK18: 0.021
A19: Income Tax | B19: ='Income Statement'!B69/'Income Statement'!B26 -> 0.027983857 | C19: ='Income Statement'!C69/'Income Statement'!C26 -> 0.02074614 | D19: ='Income Statement'!D69/'Income Statement'!D26 -> 0.080263034 | E19: ='Income Statement'!E69/'Income Statement'!E26 -> 0.028746255 | F19: ='Income Statement'!F69/'Income Statement'!F26 -> 0.011677697 | G19: ='Income Statement'!G69/'Income Statement'!G26 -> 0.019302466 | H19: ='Income Statement'!H69/'Income Statement'!H26 -> 0.041381541 | I19: ='Income Statement'!I69/'Income Statement'!I26 -> 0.047767078 | Q19: Current Ratio | R19: 0.44 | S19: 0.53 | T19: 0.51 | U19: 0.63 | V19: 0.44 | W19: 0.4 | X19: 0.48 | Y19: 0.51 | AB19: Total Debt Percentage of Total Equity | AC19: IND | AD19: 1.677 | AE19: 1.705 | AF19: 1.619 | AG19: 1.403 | AH19: 1.399 | AI19: 1.278 | AJ19: 1.318 | AK19: 1.245
A20: Net Income | B20: ='Income Statement'!B94/'Income Statement'!B26 -> 0.072594946 | C20: ='Income Statement'!C94/'Income Statement'!C26 -> 0.085625407 | D20: ='Income Statement'!D94/'Income Statement'!D26 -> 0.032586932 | E20: ='Income Statement'!E94/'Income Statement'!E26 -> 0.11525305 | F20: ='Income Statement'!F94/'Income Statement'!F26 -> 0.10000035 | G20: ='Income Statement'!G94/'Income Statement'!G26 -> 0.082283311 | H20: ='Income Statement'!H94/'Income Statement'!H26 -> 0.087114742 | I20: ='Income Statement'!I94/'Income Statement'!I26 -> -0.15775978 | Q20: Quick Ratio | R20: 0.31 | S20: 0.36 | T20: 0.41 | U20: 0.55 | V20: 0.31 | W20: 0.28 | X20: 0.37 | Y20: 0.4 | AC20: FE | AD20: 1.751 | AE20: 2.282 | AF20: 2.035 | AG20: 2.75 | AH20: 3.382 | AI20: 3.011 | AJ20: 2.862 | AK20: 4.98
Q21: Accounts Receivable Turnover | R21: 7.48 | S21: 7.07 | T21: 8.13 | V21: 7.99 | W21: 8.57 | X21: 8.48 | Y21: 8.1 | AB21: Current Ratio | AC21: IND | AD21: 0.67 | AE21: 0.74 | AF21: 0.66 | AG21: 0.82 | AH21: 0.66 | AI21: 0.64 | AJ21: 0.67 | AK21: 0.74
Q22: Payables Turnover | R22: 5.86 | S22: 5.85 | T22: 6.11 | V22: 5.6 | W22: 5.85 | X22: 6.24 | Y22: 5.85 | AC22: FE | AD22: 0.56 | AE22: 0.48 | AF22: 0.61 | AG22: 0.73 | AH22: 0.74 | AI22: 0.5 | AJ22: 0.52 | AK22: 0.76
B23: BALANCE SHEET -COMMON SIZING | AB23: Quick Ratio | AC23: IND | AD23: 0.46 | AE23: 0.49 | AF23: 0.5 | AG23: 0.58 | AH23: 0.5 | AI23: 0.46 | AJ23: 0.5 | AK23: 0.55
AC24: FE | AD24: 0.45 | AE24: 0.38 | AF24: 0.5 | AG24: 0.67 | AH24: 0.68 | AI24: 0.44 | AJ24: 0.46 | AK24: 0.7
A25: Cash & Cash Equivalent | B25: ='Balance Sheet'!B23/'Balance Sheet'!B72 -> 0.0021328375 | C25: ='Balance Sheet'!C23/'Balance Sheet'!C72 -> 0.002809331 | D25: ='Balance Sheet'!D23/'Balance Sheet'!D72 -> 0.0034700496 | E25: ='Balance Sheet'!E23/'Balance Sheet'!E72 -> 0.032179947 | F25: ='Balance Sheet'!F23/'Balance Sheet'!F72 -> 0.038997807 | G25: ='Balance Sheet'!G23/'Balance Sheet'!G72 -> 0.014822304 | H25: ='Balance Sheet'!H23/'Balance Sheet'!H72 -> 0.0091606111 | I25: ='Balance Sheet'!I23/'Balance Sheet'!I72 -> 0.013914899 | Q25: Net Margin - % | R25: 0.159 | S25: 0.152 | T25: 0.117 | U25: 0.1 | V25: 0.152 | W25: 0.222 | X25: 0.097 | Y25: 0.029 | AB25: Accounts Receivable Turnover | AC25: IND | AD25: 6.47 | AE25: 6.28 | AF25: 5.47 | AG25: 4.5 | AH25: 5.86 | AI25: 5.77 | AJ25: 6.19 | AK25: 6.14
A26: Receivables | B26: ='Balance Sheet'!B25/'Balance Sheet'!B72 -> 0.035220146 | C26: ='Balance Sheet'!C25/'Balance Sheet'!C72 -> 0.032481013 | D26: ='Balance Sheet'!D25/'Balance Sheet'!D72 -> 0.034072212 | E26: ='Balance Sheet'!E25/'Balance Sheet'!E72 -> 0.028151987 | F26: ='Balance Sheet'!F25/'Balance Sheet'!F72 -> 0.032363314 | G26: ='Balance Sheet'!G25/'Balance Sheet'!G72 -> 0.030590322 | H26: ='Balance Sheet'!H25/'Balance Sheet'!H72 -> 0.037715587 | I26: ='Balance Sheet'!I25/'Balance Sheet'!I72 -> 0.034361163 | Q26: Return on Average Total Assets | R26: 0.03 | S26: 0.028 | T26: 0.026 | U26: 0.018 | V26: 0.026 | W26: 0.04 | X26: 0.02 | Y26: 0.006 | AC26: FE | AD26: 7.89 | AE26: 8.16 | AF26: 8.74 | AG26: 8.19 | AH26: 7.9 | AI26: 7.87 | AJ26: 7.6 | AK26: 7.13
A27: Inventory | B27: ='Balance Sheet'!B30/'Balance Sheet'!B72 -> 0.01054874 | C27: ='Balance Sheet'!C30/'Balance Sheet'!C72 -> 0.010498841 | D27: ='Balance Sheet'!D30/'Balance Sheet'!D72 -> 0.00913069 | E27: ='Balance Sheet'!E30/'Balance Sheet'!E72 -> 0.0057227687 | F27: ='Balance Sheet'!F30/'Balance Sheet'!F72 -> 0.0071293457 | G27: ='Balance Sheet'!G30/'Balance Sheet'!G72 -> 0.0066429307 | H27: ='Balance Sheet'!H30/'Balance Sheet'!H72 -> 0.0062900495 | I27: ='Balance Sheet'!I30/'Balance Sheet'!I72 -> 0.0055849261 | Q27: Total Debt Percentage of Total Equity | R27: 1.768 | S27: 1.76 | T27: 1.667 | U27: 1.649 | V27: 1.512 | W27: 1.462 | X27: 1.597 | Y27: 1.965 | AB27: Payables Turnover | AC27: IND | AD27: 5.9 | AE27: 5.63 | AF27: 6.11 | AG27: 5.565 | AH27: 5.22 | AI27: 5.85 | AJ27: 6.24 | AK27: 5.85
A28: Current Assets | B28: ='Balance Sheet'!B37/'Balance Sheet'!B72 -> 0.05333951 | C28: ='Balance Sheet'!C37/'Balance Sheet'!C72 -> 0.052658623 | D28: ='Balance Sheet'!D37/'Balance Sheet'!D72 -> 0.052376971 | E28: ='Balance Sheet'!E37/'Balance Sheet'!E72 -> 0.071249411 | F28: ='Balance Sheet'!F37/'Balance Sheet'!F72 -> 0.083528215 | G28: ='Balance Sheet'!G37/'Balance Sheet'!G72 -> 0.05777644 | H28: ='Balance Sheet'!H37/'Balance Sheet'!H72 -> 0.059705959 | I28: ='Balance Sheet'!I37/'Balance Sheet'!I72 -> 0.073597329 | Q28: Asset Turnover | R28: 0.19 | S28: 0.18 | T28: 0.22 | U28: 0.18 | V28: 0.17 | W28: 0.18 | X28: 0.21 | Y28: 0.21 | AC28: FE | AD28: 4.06 | AE28: 4.26 | AF28: 4.88 | AG28: 5.36 | AH28: 4.74 | AI28: 4.71 | AJ28: 5.34 | AK28: 4.76
A29: Account Payables | B29: ='Balance Sheet'!B75/'Balance Sheet'!B72 -> 0.030262855 | C29: ='Balance Sheet'!C75/'Balance Sheet'!C72 -> 0.027928738 | D29: ='Balance Sheet'!D75/'Balance Sheet'!D72 -> 0.032597304 | E29: ='Balance Sheet'!E75/'Balance Sheet'!E72 -> 0.020756361 | F29: ='Balance Sheet'!F75/'Balance Sheet'!F72 -> 0.018599299 | G29: ='Balance Sheet'!G75/'Balance Sheet'!G72 -> 0.023758248 | H29: ='Balance Sheet'!H75/'Balance Sheet'!H72 -> 0.024087055 | I29: ='Balance Sheet'!I75/'Balance Sheet'!I72 -> 0.019570761 | Q29: Current Ratio | R29: 0.67 | S29: 0.77 | T29: 0.66 | U29: 0.82 | V29: 0.71 | W29: 0.78 | X29: 0.67 | Y29: 0.74
