Workbook

Sheet Balance Sheet
A1: Company Fundamentals - Balance Sheet
A2: Company Name | B2: Altus Group Ltd (AIF.TO)
A3: Country of Exchange | B3: Canada
A4: Country of Headquarters | B4: Canada
A5: TRBC Industry Group | B5: Real Estate Operations
A6: CF Template | B6: IND
A7: Consolidation Basis | B7: Consolidated
A8: Scaling | B8: Millions
A9: Period | B9: Annual
A10: Export Date | B10: 46068.684
A11: Statement Data | B11: 2015 | C11: 2016 | D11: 2017 | E11: 2018 | F11: 2019 | G11: 2020 | H11: 2021 | I11: 2022 | J11: 2023 | K11: 2024
A12: Period End Date | B12: 42369 | C12: 42735 | D12: 43100 | E12: 43465 | F12: 43830 | G12: 44196 | H12: 44561 | I12: 44926 | J12: 45291 | K12: 45657
A13: Statement Date | B13: 42368 | C13: 42734 | D13: 43189 | E13: 43464 | F13: 43829 | G13: 44195 | H13: 44560 | I13: 44925 | J13: 45290 | K13: 45656
A14: Standardized Currency | B14: CAD | C14: CAD | D14: CAD | E14: CAD | F14: CAD | G14: CAD | H14: CAD | I14: CAD | J14: CAD | K14: CAD
A15: Template Type | B15: Industrial - Differentiated | C15: Industrial - Differentiated | D15: Industrial - Differentiated | E15: Industrial - Differentiated | F15: Industrial - Differentiated | G15: Industrial - Differentiated | H15: Industrial - Differentiated | I15: Industrial - Differentiated | J15: Industrial - Differentiated | K15: Industrial - Differentiated
A17: Balance Sheet - Company Specific (Currency: Canadian Dollar)
A18: Field Name | B18: 30-12-2015 | C18: 30-12-2016 | D18: 30-12-2017 | E18: 30-12-2018 | F18: 30-12-2019 | G18: 30-12-2020 | H18: 30-12-2021 | I18: 30-12-2022 | J18: 30-12-2023 | K18: 30-12-2024
A19: Cash and cash equivalents | B19: 19.6 | C19: 43.67 | D19: 28.07 | E19: 48.74 | F19: 60.26 | G19: 69.64 | H19: 51.27 | I19: 55.27 | J19: 41.89 | K19: 41.88
A20: Cash on hand | H20: 49.54 | I20: 54.77 | J20: 41.89
A21: Short-term deposits | H21: 1.74 | I21: 0.5 | J21: 0
A22: Trade receivables and other | B22: 134.5 | C22: 137.4 | D22: 143.67 | E22: 154.3 | F22: 181.96 | G22: 193.07 | H22: 223.32 | I22: 255.52 | J22: 250.46 | K22: 144.81
A23: Trade Receivable, Gross | B23: 104.11 | C23: 109.98 | D23: 108.74
A24: Allowance for Doubtful Accounts | B24: -8.14 | C24: -8.19 | D24: -7.85
A25: Contract assets: unbilled revenue on customer contracts (1) | B25: 28.71 | C25: 26.01 | D25: 32.45
A26: Prepayments | B26: 8.85 | C26: 9.26 | D26: 9.21
A27: Other receivables | B27: 1.57 | C27: 0.96 | D27: 1.11
A28: Receivables from related parties | B28: 0 | C28: 0
A29: Less non-current portion: prepayments | B29: -0.59 | C29: -0.61
A30: Income taxes recoverable | B30: 0.79 | C30: 4.53 | D30: 5.68 | E30: 6.02 | F30: 2.4 | G30: 3.39 | H30: 3.28 | I30: 7.4 | J30: 9.53 | K30: 5.1
A31: Derivative financial instruments | B31: 0.03 | C31: 0.62 | D31: 1.02 | E31: 0.48 | F31: 1.45 | G31: 2.48 | H31: 5.87 | I31: 1.69 | J31: 0.68 | K31: 8.93
A32: Assets held for sale | K32: 282.23
A33: Total current assets | B33: 154.93 | C33: 186.22 | D33: 178.44 | E33: 209.54 | F33: 246.07 | G33: 268.57 | H33: 283.73 | I33: 319.88 | J33: 302.56 | K33: 482.95
A34: Trade receivables and other | B34: 0.59 | C34: 0.61 | D34: 4.97 | E34: 8.98 | F34: 3.7 | G34: 1.37 | H34: 2.82 | I34: 6.97 | J34: 10.51 | K34: 9.62
A35: Contract assets: Unbilled revenue on customer contracts | D35: 0.37
A36: Prepayments | D36: 0.69
A37: Promissory note receivable | D37: 3.91
A38: Derivative financial instruments | B38: 0.04 | C38: 3.41 | D38: 6.03 | E38: 0.61 | F38: 5.98 | G38: 8.8 | H38: 15.66 | I38: 18.52 | J38: 8.13 | K38: 9.98
A39: Investments | B39: 17.45 | C39: 23.19 | D39: 108.07 | E39: 4.9 | F39: 11.48 | G39: 10.36 | H39: 20.81 | I39: 19.31 | J39: 14.51 | K39: 14.58
A40: Deferred tax assets | B40: 19.71 | C40: 21.96 | D40: 15.29 | E40: 19.58 | F40: 22.16 | G40: 19.93 | H40: 24.09 | I40: 28.86 | J40: 30.65 | K40: 56.8
A41: Property, plant and equipment, Gross | B41: 64.44 | G41: 49.63
...

Sheet Income Statement
A1: Company Fundamentals - Income Statement
A2: Company Name | B2: Altus Group Ltd (AIF.TO)
A3: Country of Exchange | B3: Canada
A4: Country of Headquarters | B4: Canada
A5: TRBC Industry Group | B5: Real Estate Operations
A6: CF Template | B6: IND
A7: Consolidation Basis | B7: Consolidated
A8: Scaling | B8: Millions
A9: Period | B9: Annual
A10: Export Date | B10: 46068.684
A11: Statement Data | B11: 2015 | C11: 2016 | D11: 2017 | E11: 2018 | F11: 2019 | G11: 2020 | H11: 2021 | I11: 2022 | J11: 2023 | K11: 2024
A12: Period End Date | B12: 42369 | C12: 42735 | D12: 43100 | E12: 43465 | F12: 43830 | G12: 44196 | H12: 44561 | I12: 44926 | J12: 45291 | K12: 45657
A13: Statement Date | B13: 42734 | C13: 42734 | D13: 43464 | E13: 43464 | F13: 44195 | G13: 44195 | H13: 44560 | I13: 44925 | J13: 45290 | K13: 45656
A14: Standardized Currency | B14: CAD | C14: CAD | D14: CAD | E14: CAD | F14: CAD | G14: CAD | H14: CAD | I14: CAD | J14: CAD | K14: CAD
A15: Template Type | B15: Industrial - Operating | C15: Industrial - Operating | D15: Industrial - Operating | E15: Industrial - Operating | F15: Industrial - Operating | G15: Industrial - Operating | H15: Industrial - Operating | I15: Industrial - Operating | J15: Industrial - Operating | K15: Industrial - Operating
A17: Income Statement - Company Specific (Currency: Canadian Dollar)
A18: Field Name | B18: 30-12-2015 | C18: 30-12-2016 | D18: 30-12-2017 | E18: 30-12-2018 | F18: 30-12-2019 | G18: 30-12-2020 | H18: 30-12-2021 | I18: 30-12-2022 | J18: 30-12-2023 | K18: 30-12-2024
A19: Revenues | B19: 416.41 | C19: 442.89 | D19: 476.56 | E19: 510.43 | F19: 525.72 | G19: 561.16 | H19: 625.39 | I19: 735.45 | J19: 772.84 | K19: 519.73
A20: Total Revenue | B20: 416.41 | C20: 442.89 | D20: 476.56 | E20: 510.43 | F20: 525.72 | G20: 561.16 | H20: 625.39 | I20: 735.45 | J20: 772.84 | K20: 519.73
A21: Employee compensation | B21: 260.35 | C21: 274.2 | D21: 295.17 | E21: 330.61 | F21: 329.09 | G21: 354.95 | H21: 401.46 | I21: 463.95 | J21: 481.77 | K21: 336.33
A22: Non-cash share-based compensation costs | F22: 5.64 | G22: 10.26 | H22: 19.45 | I22: 24.54 | J22: 19.79 | K22: 13.29
A23: Gain (loss) on equity derivatives net | F23: -1.11 | G23: 0.47 | H23: -2.04
A24: Gain (loss) on equity derivatives net of mark to market adjustments | I24: 2.48 | J24: 4.59 | K24: -2.89
A25: Employee compensation - Balancing value | F25: 324.56 | G25: 344.22 | H25: 384.04 | I25: 436.92 | J25: 457.38 | K25: 325.93
A26: Occupancy | B26: 18.55 | C26: 19.96 | D26: 20.71 | E26: 21.34 | F26: 7.29 | G26: 7.59 | H26: 7.74 | I26: 7.03 | J26: 7.85 | K26: 5.4
A27: Other operating | B27: 76.06 | C27: 79.82 | D27: 87.44 | E27: 98.04 | F27: 101.89 | G27: 102.19 | H27: 123.02 | I27: 152.89 | J27: 176.48 | K27: 100.46
A28: Unrealized foreign exchange gain (loss) | F28: 0.99 | G28: 0.17 | H28: 1.1 | I28: -3.85 | J28: 1.62 | K28: 0.76
A29: Gain (loss) on disposal of PPE and Intangibles | F29: 0.36 | G29: 0.46 | H29: -0.25 | I29: 0.83 | J29: 0.45 | K29: -2.5
A30: Share-based compensation | F30: 0 | G30: 0.75 | H30: 0
A31: Termination Benefits | F31: 1.75 | G31: 1.14 | H31: 0
A32: Non-Recurring Income/Expense - Other | I32: 11.74 | J32: 13.74 | K32: 5.86
A33: Office and other operating - Balancing value | F33: 98.79 | G33: 99.68 | H33: 122.17 | I33: 144.18 | J33: 160.67 | K33: 96.34
A34: Amortization of intangibles | B34: 33.04 | C34: 26.2 | D34: 29.18 | E34: 41.03 | F34: 29.53 | G34: 24.78 | H34: 29.02 | I34: 41 | J34: 40.72 | K34: 32.04
A35: Depreciation of right-of-use assets | F35: 12.32 | G35: 11.21 | H35: 12.12 | I35: 11.97 | J35: 11.12 | K35: 8.27
A36: Depreciation of property, plant and equipment | B36: 7.02 | C36: 7.23 | D36: 7.26 | E36: 8.09 | F36: 5.85 | G36: 5.62 | H36: 5.45 | I36: 6.56 | J36: 6.1 | K36: 3.71
A37: Acquisition and related transition costs (income) | B37: -0.43 | C37: 0.62 | D37: 3.32 | E37: 2.39 | F37: 0.19 | G37: -0.89 | H37: 10.14 | I37: 4.93 | J37: 3.83 | K37: 8.91
A38: Share of (profit) loss of joint venture | B38: 1.27 | C38: 2.62 | D38: 2.42 | E38: 0 | F38: 0 | G38: -0.46 | H38: -1.19 | I38: -3.01 | J38: -3.15 | K38: -2.95
A39: Restructuring costs (recovery) | B39: 2.69 | C39: 4.06 | D39: 4.74 | E39: 6.37 | F39: -0.3 | G39: 11.98 | H39: 0.02 | I39: 38.9 | J39: 0.39 | K39: 12.05
A40: Impairment of right of use assets | I40: 6.91 | J40: -0.56
A41: Restructuring costs (recovery) - Balancing value | I41: 31.99 | J41: 0.95
...

Sheet Cash Flow
A1: Company Fundamentals - Cash Flow
A2: Company Name | B2: Altus Group Ltd (AIF.TO)
A3: Country of Exchange | B3: Canada
A4: Country of Headquarters | B4: Canada
A5: TRBC Industry Group | B5: Real Estate Operations
A6: CF Template | B6: IND
A7: Consolidation Basis | B7: Consolidated
A8: Scaling | B8: Millions
A9: Period | B9: Annual
A10: Export Date | B10: 46068.684
A11: Statement Data | B11: 2015 | C11: 2016 | D11: 2017 | E11: 2018 | F11: 2019 | G11: 2020 | H11: 2021 | I11: 2022 | J11: 2023 | K11: 2024
A12: Period End Date | B12: 42369 | C12: 42735 | D12: 43100 | E12: 43465 | F12: 43830 | G12: 44196 | H12: 44561 | I12: 44926 | J12: 45291 | K12: 45657
A13: Statement Date | B13: 42368 | C13: 42734 | D13: 43464 | E13: 43464 | F13: 43829 | G13: 44195 | H13: 44560 | I13: 44925 | J13: 45290 | K13: 45656
A14: Standardized Currency | B14: CAD | C14: CAD | D14: CAD | E14: CAD | F14: CAD | G14: CAD | H14: CAD | I14: CAD | J14: CAD | K14: CAD
A15: Template Type | B15: Industrial - Indirect | C15: Industrial - Indirect | D15: Industrial - Indirect | E15: Industrial - Indirect | F15: Industrial - Indirect | G15: Industrial - Indirect | H15: Industrial - Indirect | I15: Industrial - Indirect | J15: Industrial - Indirect | K15: Industrial - Indirect
A17: Cash Flow - Company Specific (Currency: Canadian Dollar)
A18: Field Name | B18: 30-12-2015 | C18: 30-12-2016 | D18: 30-12-2017 | E18: 30-12-2018 | F18: 30-12-2019 | G18: 30-12-2020 | H18: 30-12-2021 | I18: 30-12-2022 | J18: 30-12-2023 | K18: 30-12-2024
A19: Profit (loss) before income taxes | B19: 10.1 | C19: 21.08 | D19: 137.86 | E19: -17.8 | F19: 25.15 | G19: 37.56 | H19: 34.2 | I19: 3.88 | J19: 22.33 | K19: 8.76
A20: Depreciation of right-of-use assets | F20: 13.44 | G20: 11.26 | H20: 12.12 | I20: 11.97 | J20: 11.12 | K20: 9.95
A21: Depreciation of property, plant and equipment | B21: 7.02 | C21: 7.23 | D21: 7.26 | E21: 8.09 | F21: 7.84 | G21: 5.73 | H21: 5.45 | I21: 6.56 | J21: 6.1 | K21: 4.55
A22: Amortization of intangibles | B22: 33.04 | C22: 26.2 | D22: 29.18 | E22: 41.03 | F22: 30 | G22: 24.79 | H22: 29.02 | I22: 41 | J22: 40.72 | K22: 35.92
A23: Amortization of lease inducements | B23: 0.32 | C23: -0.26 | D23: 0.9 | E23: 0.69 | F23: 0
A24: Finance costs (income), net - leases | F24: 2.89 | G24: 2.56 | H24: 2.22 | I24: 1.91 | J24: 1.22 | K24: 1.19
A25: Tax credits recorded through employee compensation | B25: -0.02 | C25: -0.13
A26: Amortization of capitalized software development costs | B26: 0.53 | C26: 0.52 | D26: 0.29 | E26: 0
A27: Finance costs (income), net - other | B27: 11.25 | C27: 4.55 | D27: 3.63 | E27: 6.7 | F27: 6.57 | G27: 4.12 | H27: 4.13 | I27: 5.28 | J27: 23.88 | K27: 17.98
A28: Share-based compensation | B28: 5.95 | C28: 7.12 | D28: 7.82 | E28: 9.46 | F28: 9.84 | G28: 15.4 | H28: 23.94 | I28: 29.38 | J28: 23.07 | K28: 23.67
A29: Unrealized foreign exchange (gain) loss | B29: -1.68 | C29: 1.79 | D29: 0.85 | E29: -0.98 | F29: 0.99 | G29: 0.17 | H29: 1.1 | I29: -3.85 | J29: 1.62 | K29: -0.34
A30: (Gain) loss on investments | D30: -115.18 | E30: -0.04 | F30: -0.28 | G30: -0.02 | H30: -2.93 | I30: 0.16 | J30: 0.3 | K30: -0.45
A31: (Gain) loss on disposal of property, plant and equipment and intangibles | B31: 0.42 | C31: 0.12 | D31: 0.86 | E31: 1.62 | F31: 0.27 | G31: 0.52 | H31: -0.25 | I31: 0.83 | J31: 0.45 | K31: -2.02
A32: (Gain) loss on equity derivatives | B32: 0.21 | C32: -3.96 | D32: -1.24 | E32: 4.82 | F32: -6.84 | G32: -3.99 | H32: -10.25 | I32: 8.74 | J32: 8.6 | K32: -9.94
A33: Impairment charge leases | C33: 12.5 | E33: 13.7 | F33: 0.07 | G33: 0.04 | H33: 0
A34: Impairment charge - goodwill | F34: 6.4 | G34: 0
A35: Share of (profit) loss of joint venture | B35: 1.27 | C35: 2.62 | D35: 2.42 | E35: 0 | G35: -0.46 | H35: -1.19 | I35: -3.01 | J35: -3.15 | K35: -2.95
A36: Operating working capital | B36: -1.68 | C36: 11.74 | D36: 9.41 | E36: -3.83 | F36: -23.11 | G36: -1.91 | H36: -18.83 | I36: 0.18 | J36: -24.12 | K36: 11.7
A37: Net cash generated by (used in) operations | C37: 81.18 | D37: 84.08 | E37: 63.45 | F37: 73.23 | G37: 94.86 | H37: 78.72 | I37: 104.25 | J37: 107.58 | K37: 122.06
A38: Interest paid on borrowings | B38: -7.2 | C38: -4.25 | D38: -4.31 | E38: -5.37 | F38: -5.04 | G38: -3.55 | H38: -3.61 | I38: -11.73 | J38: -20.27 | K38: -18.06
A39: Interest paid on leases | F39: -2.88 | G39: -2.56 | H39: -2.22 | I39: -1.91 | J39: -1.22 | K39: -1.19
A40: Income taxes paid | B40: -8.61 | C40: -10.41 | D40: -23.77 | E40: -13.52 | F40: -15.45 | G40: -19.05 | H40: -19.55 | I40: -14.83 | J40: -14.89 | K40: -23.59
A41: Income taxes refunded | B41: 0.71 | C41: 0.71 | D41: 1.84 | E41: 4.93 | F41: 2.58 | G41: 2.6 | H41: 2.96 | I41: 1.31 | J41: 0.24 | K41: 0.7
...

Sheet Financials
A1: Profitability
B2: 2015 | C2: 2016 | D2: 2017 | E2: 2018 | F2: 2019 | G2: 2020 | H2: 2021 | I2: 2022 | J2: 2023 | K2: 2024
A3: GPM | B3: 1 | C3: 1 | D3: 1 | E3: 1 | F3: 1 | G3: 1 | H3: 1 | I3: 1 | J3: 1 | K3: 1
A4: NPM | B4: ='Income Statement'!B82/'Income Statement'!B20 -> 0.022213684 | C4: ='Income Statement'!C82/'Income Statement'!C20 -> 0.03222019 | D4: ='Income Statement'!D82/'Income Statement'!D20 -> 0.22960383 | E4: ='Income Statement'!E82/'Income Statement'!E20 -> -0.036126403 | F4: ='Income Statement'!F82/'Income Statement'!F20 -> 0.034600167 | G4: ='Income Statement'!G82/'Income Statement'!G20 -> 0.038188752 | H4: ='Income Statement'!H82/'Income Statement'!H20 -> 0.041078367 | I4: ='Income Statement'!I82/'Income Statement'!I20 -> -0.0012101434 | ... K4: ='Income Statement'!K82/'Income Statement'!K20 -> 0.025821099
A5: ROA | B5: ='Income Statement'!B82/'Balance Sheet'!B81 -> 0.015475473 | C5: ='Income Statement'!C82/'Balance Sheet'!C81 -> 0.024151646 | D5: ='Income Statement'!D82/'Balance Sheet'!D81 -> 0.15069135 | E5: ='Income Statement'!E82/'Balance Sheet'!E81 -> -0.028016652 | F5: ='Income Statement'!F82/'Balance Sheet'!F81 -> 0.024743923 | G5: ='Income Statement'!G82/'Balance Sheet'!G81 -> 0.029140604 | H5: ='Income Statement'!H82/'Balance Sheet'!H81 -> 0.021422615 | I5: ='Income Statement'!I82/'Balance Sheet'!I81 -> -0.00070417521 | ... K5: ='Income Statement'!K82/'Balance Sheet'!K81 -> 0.010727761
A6: ROE | B6: ='Income Statement'!B82/'Balance Sheet'!B130 -> 0.026383343 | C6: ='Income Statement'!C82/'Balance Sheet'!C130 -> 0.041897883 | D6: ='Income Statement'!D82/'Balance Sheet'!D130 -> 0.26554385 | E6: ='Income Statement'!E82/'Balance Sheet'!E130 -> -0.051446587 | F6: ='Income Statement'!F82/'Balance Sheet'!F130 -> 0.05057695 | G6: ='Income Statement'!G82/'Balance Sheet'!G130 -> 0.055887339 | H6: ='Income Statement'!H82/'Balance Sheet'!H130 -> 0.043580783 | I6: ='Income Statement'!I82/'Balance Sheet'!I130 -> -0.0014836548 | ... K6: ='Income Statement'!K82/'Balance Sheet'!K130 -> 0.021742653
A7: OPM | B7: ='Income Statement'!B46/'Income Statement'!B20 -> 0.051271583 | C7: ='Income Statement'!C46/'Income Statement'!C20 -> 0.0578699 | D7: ='Income Statement'!D46/'Income Statement'!D20 -> 0.29689861 | E7: ='Income Statement'!E46/'Income Statement'!E20 -> -0.021746371 | F7: ='Income Statement'!F46/'Income Statement'!F20 -> 0.076333409 | G7: ='Income Statement'!G46/'Income Statement'!G20 -> 0.078747594 | H7: ='Income Statement'!H46/'Income Statement'!H20 -> 0.06483954 | I7: ='Income Statement'!I46/'Income Statement'!I20 -> 0.015065606 | ... K7: ='Income Statement'!K46/'Income Statement'!K20 -> 0.01722048
A10: Liquidity
B11: 2015 | C11: 2016 | D11: 2017 | E11: 2018 | F11: 2019 | G11: 2020 | H11: 2021 | I11: 2022 | J11: 2023 | K11: 2024
A12: Current Ratio | B12: ='Balance Sheet'!B33/'Balance Sheet'!B100 -> 1.8350113 | C12: ='Balance Sheet'!C33/'Balance Sheet'!C100 -> 1.7816686 | D12: ='Balance Sheet'!D33/'Balance Sheet'!D100 -> 1.6846677 | E12: ='Balance Sheet'!E33/'Balance Sheet'!E100 -> 1.6739096 | F12: ='Balance Sheet'!F33/'Balance Sheet'!F100 -> 0.86763513 | G12: ='Balance Sheet'!G33/'Balance Sheet'!G100 -> 1.7532968 | H12: ='Balance Sheet'!H33/'Balance Sheet'!H100 -> 1.3515458 | I12: ='Balance Sheet'!I33/'Balance Sheet'!I100 -> 1.3336113 | ... K12: ='Balance Sheet'!K33/'Balance Sheet'!K100 -> 1.6763277
A16: Operating
B17: 2015 | C17: 2016 | D17: 2017 | E17: 2018 | F17: 2019 | G17: 2020 | H17: 2021 | I17: 2022 | J17: 2023 | K17: 2024
A18: Accounts Receivable Turnover | B18: 3.3 | C18: 3.42 | D18: 3.49 | E18: 3.4 | F18: 3.05 | G18: 2.95 | H18: 2.96 | I18: 3 | J18: 2.96 | K18: 2.54
A19: Average Receivables Collection Days | B19: 110.98 | C19: 107.07 | D19: 104.76 | E19: 107.72 | F19: 119.98 | G19: 124.19 | H19: 123.79 | I19: 121.8 | J19: 123.82 | K19: 144.33
A22: Leverage
B23: 2015 | C23: 2016 | D23: 2017 | E23: 2018 | F23: 2019 | G23: 2020 | H23: 2021 | I23: 2022 | J23: 2023 | K23: 2024
A24: TDTA | B24: 22.83 | C24: 20.98 | D24: 20.77 | E24: 19.66 | F24: 29.14 | G24: 25.29 | H24: 29.86 | I24: 29.92 | J24: 29.27 | K24: 25.55
A25: TDTC | B25: 28.01 | C25: 26.68 | D25: 26.79 | E25: 26.52 | F25: 37.33 | G25: 32.66 | H25: 37.67 | I25: 38.66 | J25: 37.11 | K25: 34.12
A26: TDTE | B26: 38.91 | C26: 36.39 | D26: 36.6 | E26: 36.09 | F26: 59.57 | G26: 48.51 | H26: 60.75 | I26: 63.04 | J26: 59.01 | K26: 51.79
A27: ICR | B27: 2.2 | C27: 7.3 | D27: 7.49 | E27: 1.87 | F27: 3.78 | G27: 6.39 | H27: 7.4 | I27: 4.38 | J27: 3.14 | K27: 1.79

Sheet Process_CSCF
A1: Historical FCF | L1: Projected FCF
B2: 2015 | C2: 2016 | D2: 2017 | E2: 2018 | F2: 2019 | G2: 2020 | H2: 2021 | I2: 2022 | J2: 2023 | K2: 2024 | L2: 2025 | M2: 2026 | N2: 2027 | O2: 2028 | P2: 2029 | Q2: 2030 & >
A3: Cash Flow from Operation | B3: {='Cash Flow'!B51:K51} -> 48.14 | C3: 67.24 | D3: 57.84 | E3: 49.49 | F3: 52.43 | G3: 72.3 | H3: 56.31 | I3: 77.08 | J3: 71.43 | K3: 79.92
A4: Capital Expenditure | B4: {='Cash Flow'!B54:K54} -> -12.32 | C4: -4.23 | D4: -11.79 | E4: -11.54 | F4: -5.79 | G4: -3.58 | H4: -5.96 | I4: -5.43 | J4: -4.83 | K4: -1.39
A5: FCF | B5: =B3+B4 -> 35.82 | C5: =C3+C4 -> 63.01 | D5: =D3+D4 -> 46.05 | E5: =E3+E4 -> 37.95 | F5: =F3+F4 -> 46.64 | G5: =G3+G4 -> 68.72 | H5: =H3+H4 -> 50.35 | I5: =I3+I4 -> 71.65 | ... K5: =K3+K4 -> 78.53 | L5: =K5*(1+L7) -> 82.4565 | M5: =L5*(1+M7) -> 86.167042 | N5: =M5*(1+N7) -> 89.613724 | O5: =N5*(1+O7) -> 92.750205 | P5: =O5*(1+P7) -> 95.532711 | Q5: =P5*(1+DCF_CSCF!B8)/(L12-DCF_CSCF!B8) -> 1801.6928
A6: Growth Rate (YoY) | B6: =(C5-B5)/B5 -> 0.75907314 | C6: =(D5-C5)/C5 -> -0.26916362 | D6: =(E5-D5)/D5 -> -0.17589577 | E6: =(F5-E5)/E5 -> 0.22898551 | F6: =(G5-F5)/F5 -> 0.47341338 | G6: =(H5-G5)/G5 -> -0.26731665 | H6: =(I5-H5)/H5 -> 0.42303873 | I6: =(J5-I5)/I5 -> -0.070481507 | J6: =(K5-J5)/J5 -> 0.17912913
A7: Shor-term Growth Rates (Assumptions) | L7: 0.05 | M7: =L7-0.5% -> 0.045 | N7: =M7-0.5% -> 0.04 | O7: =N7-0.5% -> 0.035 | P7: =O7-0.5% -> 0.03
B8: 2015-2024 | C8: 2020-2024
A9: Average Growth Rate | B9: =AVERAGE(B6:J6) -> 0.14230915 | C9: =AVERAGE(G6:J6) -> 0.066092426 | K9: Industry Name | L9: Number of Firms | M9: Beta | N9: Cost of Equity | O9: E/(D+E) | P9: Std Dev in Stock | Q9: Cost of Debt | R9: Tax Rate | S9: After-tax Cost of Debt | T9: D/(D+E) | U9: Cost of Capital | V9: Cost of Capital (Local Currency)
A10: Median Growth Rate | B10: =MEDIAN(B6:J6) -> 0.17912913 | C10: =MEDIAN(G6:J6) -> 0.054323811 | K10: Real Estate (Operations & Services) | L10: 54 | M10: 0.96549741 | N10: 0.082561184 | O10: 0.80229597 | P10: 0.50559626 | Q10: 0.052913 | R10: 0.086974403 | S10: 0.03968475 | T10: 0.19770403 | U10: 0.07408434 | V10: 0.07408434
A11: CAGR | B11: =((K5/B5)^(1/10)-1) -> 0.081660578 | C11: =((K5/G5)^(1/10)-1) -> 0.013433473
K12: WAACC | L12: =(O10*N10)+(T10*S10) -> 0.07408434

Sheet DCF_CSCF
A1: Input and Assumptions
J2: Cells in YELLOW are input
A3: Last Updated on | B3: 46073
A4: Last Financial Statement Date | B4: ='Balance Sheet'!K12 -> 45657 | J4: Cells in BEIGE are looked up
A5: Current Market Price | B5: 40.25
A6: # of share outstanding in million (FY 2024) | B6: 40.4 | J6: Cells in WHITE are calculated
A7: Initial FCF Growth (Short-term Rate) | B7: =Process_CSCF!C10 -> 0.054323811 | C7: Growth is phased down from the initial rate
A8: Growth rate of FCF (long term growth) | B8: 0.02 | J8: Cells in RED are output
A9: Discount Rate (WACC) | B9: =Process_CSCF!L12 -> 0.07408434
A13: Investment Criteria
A15: Decision | B15: Difference Between Value and Price
A16: Sell | B16: =ROUND((B37-B5) / B5, 3) -> -0.126 | C16: {=_xlfn.IFS(B16>0.1,"BUY",B16<-0.1,"SELL",TRUE,"HOLD")} -> SELL
A17: Underperform
A18: HOLD
A19: BUY
A20: Strong Buy
A22: Free Cash Flow Projection
A24: Year | B24: Today | C24: Yr 1 | D24: Yr 2 | E24: Yr 3 | F24: Yr 4 | G24: Yr 5 | H24: Terminal Value @ Yr 5
A26: FCF | B26: =Process_CSCF!K5 -> 78.53 | C26: =Process_CSCF!L5 -> 82.4565 | D26: =Process_CSCF!M5 -> 86.167042 | E26: =Process_CSCF!N5 -> 89.613724 | F26: =Process_CSCF!O5 -> 92.750205 | G26: =Process_CSCF!P5 -> 95.532711
A27: FCF with Terminal Value | B27: {=Process_CSCF!K5:Q5} -> 78.53 | C27: 82.4565 | D27: 86.167042 | E27: 89.613724 | F27: 92.750205 | G27: 95.532711 | H27: 1801.6928
A28: Present Value | B28: =B27/(1+$B$9)^0 -> 78.53 | C28: =C27/(1+$B$9)^1 -> 76.769111 | D28: =D27/(1+$B$9)^2 -> 74.690337 | E28: =E27/(1+$B$9)^3 -> 72.320159 | F28: =F27/(1+$B$9)^4 -> 69.688535 | G28: =G27/(1+$B$9)^5 -> 66.828264 | H28: =H27/(1+$B$9)^5 -> 1260.3432
A31: Free Cash Flow Projection
A33: Enterprise Value | B33: =SUM(B28:H28) -> 1699.1696
A34: Firm Cash | B34: ='Balance Sheet'!K19 -> 41.88
A35: Firm Debt | B35: ='Balance Sheet'!K103+'Balance Sheet'!K94 -> 319.65
A36: Equity Value | B36: =B33+B34-B35 -> 1421.3996
A37: Fair Share Price | B37: =B36/B6 -> 35.183158
A38: Recommendation | B38: SELL
A40: Sensitivity Analysis
A41: Terminal Growth Rate vs Discount Rate (CSCF)
B42: =B37 -> 35.183158 | C42: 0.055 | D42: 0.06 | E42: 0.0741 | F42: 0.08 | G42: 0.085 | H42: 0.09
B43: 0 | C43: 28.892736 | D43: 28.191396 | E43: 26.312668 | F43: 25.567677 | G43: 24.954345 | H43: 24.356996
B44: 0.005 | C44: 30.791237 | D44: 30.045541 | E44: 28.048268 | F44: 27.256384 | G44: 26.604498 | H44: 25.969648
B45: 0.01 | C45: 32.985989 | D45: 32.189016 | E45: 30.054698 | F45: 29.208604 | G45: 28.512149 | H45: 27.833945
B46: 0.015 | C46: 35.5522 | D46: 34.695272 | E46: 32.400715 | F46: 31.491237 | G46: 30.742669 | H46: 30.013774
B47: 0.02 | C47: 38.592896 | D47: 37.664926 | E47: 35.180503 | F47: 34.19592 | G47: 33.385604 | H47: 32.596645
B48: 0.025 | C48: 42.253075 | D48: 41.239591 | E48: 38.526619 | F48: 37.451631 | G48: 36.566987 | H48: 35.705726
B49: 0.03 | C49: 46.743521 | D49: 45.625125 | E49: 42.631761 | F49: 41.445861 | G49: 40.470028 | H49: 39.520066
B50: 0.035 | C50: 52.382879 | D50: 51.132728 | E50: 47.787233 | F50: 46.462042 | G50: 45.37169 | H50: 44.31033
B51: 0.04 | C51: 59.676768 | D51: 58.256207 | E51: 54.455268 | F51: 52.94992 | G51: 51.711449 | H51: 50.50601

Sheet Process_Pro_Forma
A1: REVENUE
A2: Historical | L2: Projected
B3: 2015 | C3: 2016 | D3: 2017 | E3: 2018 | F3: 2019 | G3: 2020 | H3: 2021 | I3: 2022 | J3: 2023 | K3: 2024 | L3: 2025 | M3: 2026 | N3: 2027 | O3: 2028 | P3: 2029
A4: Revenue | B4: {='Income Statement'!B20:K20} -> 416.41 | C4: 442.89 | D4: 476.56 | E4: 510.43 | F4: 525.72 | G4: 561.16 | H4: 625.39 | I4: 735.45 | J4: 772.84 | K4: 519.73
A5: Growth (Calculated) | B5: =(C4-B4)/B4 -> 0.063591172 | C5: =(D4-C4)/C4 -> 0.076023392 | D5: =(E4-D4)/D4 -> 0.071071848 | E5: =(F4-E4)/E4 -> 0.029955136 | F5: =(G4-F4)/F4 -> 0.067412311 | G5: =(H4-G4)/G4 -> 0.11445933 | H5: =(I4-H4)/H4 -> 0.17598618 | I5: =(J4-I4)/I4 -> 0.050839622 | J5: =(K4-J4)/J4 -> -0.32750634 | L5: =K4*(1+L7) -> 547.31918 | M5: =L5*(1+M7) -> 573.63631 | N5: =M5*(1+N7) -> 598.35068 | O5: =N5*(1+O7) -> 621.13808 | P5: =O5*(1+P7) -> 641.68762
A6: AVERAGE | B6: =AVERAGE(B5:I5) -> 0.081167375
A7: Gowth Assumptions | L7: =DCF_Pro_Forma!B10 -> 0.053083687 | M7: =L7-0.5% -> 0.048083687 | N7: =M7-0.5% -> 0.043083687 | O7: =N7-0.5% -> 0.038083687 | P7: =O7-0.5% -> 0.033083687
A9: EBIT
A10: Historical | L10: Projected
B11: 2015 | C11: 2016 | D11: 2017 | E11: 2018 | F11: 2019 | G11: 2020 | H11: 2021 | I11: 2022 | J11: 2023 | K11: 2024 | L11: 2025 | M11: 2026 | N11: 2027 | O11: 2028 | P11: 2029
A12: EBIT | B12: {='Income Statement'!B46:K46} -> 21.35 | C12: 25.63 | D12: 141.49 | E12: -11.1 | F12: 40.13 | G12: 44.19 | H12: 40.55 | I12: 11.08 | J12: 47.43 | K12: 8.95 | L12: =L5*L15 -> 32.839151 | M12: =M5*M15 -> 34.418179 | N12: =N5*N15 -> 35.901041 | O12: =O5*O15 -> 37.268285 | P12: =P5*P15 -> 38.501257
A13: EBIT Margin | B13: =B12/B4 -> 0.051271583 | C13: =C12/C4 -> 0.0578699 | D13: =D12/D4 -> 0.29689861 | E13: =E12/E4 -> -0.021746371 | F13: =F12/F4 -> 0.076333409 | G13: =G12/G4 -> 0.078747594 | H13: =H12/H4 -> 0.06483954 | I13: =I12/I4 -> 0.015065606 | ... K13: =K12/K4 -> 0.01722048
A14: AVERAGE/MEDIAN | B14: =AVERAGE(F13:K13) -> 0.052262946 | C14: =MEDIAN(F13:K13) -> 0.063105294
A15: Growth Assumptions | L15: 0.06 | M15: 0.06 | N15: 0.06 | O15: 0.06 | P15: 0.06
A17: TAX
A18: Historical | L18: Projected
B19: 2015 | C19: 2016 | D19: 2017 | E19: 2018 | F19: 2019 | G19: 2020 | H19: 2021 | I19: 2022 | J19: 2023 | K19: 2024 | L19: 2025 | M19: 2026 | N19: 2027 | O19: 2028 | P19: 2029
A20: Tax | B20: {=-('Cash Flow'!B40:K40)} -> 8.61 | C20: 10.41 | D20: 23.77 | E20: 13.52 | F20: 15.45 | G20: 19.05 | H20: 19.55 | I20: 14.83 | J20: 14.89 | K20: 23.59 | L20: =L12*$B$22 -> 8.2097878 | M20: =M12*$B$22 -> 8.6045446 | N20: =N12*$B$22 -> 8.9752602 | O20: =O12*$B$22 -> 9.3170712 | P20: =P12*$B$22 -> 9.6253142
A21: Implied Tax Rate | B21: =B20/B12 -> 0.40327869 | C21: =C20/C12 -> 0.40616465 | D21: =D20/D12 -> 0.16799774 | E21: =E20/E12 -> -1.218018 | F21: =F20/F12 -> 0.38499875 | G21: =G20/G12 -> 0.43109301 | H21: =H20/H12 -> 0.48212084 | I21: =I20/I12 -> 1.3384477 | ... K21: =K20/K12 -> 2.6357542
A22: Tax Rate (25% of EBIT) | B22: 0.25
A24: DEPRECIATION AND OTHER NON-CASH ITEMS
A25: Historical | L25: Projected
B26: 2015 | C26: 2016 | D26: 2017 | E26: 2018 | F26: 2019 | G26: 2020 | H26: 2021 | I26: 2022 | J26: 2023 | K26: 2024 | L26: 2025 | M26: 2026 | N26: 2027 | O26: 2028 | P26: 2029
A27: Depreciation & Ammortization | B27: ='Cash Flow'!B20+'Cash Flow'!B21+'Cash Flow'!B22+'Cash Flow'!B26 -> 40.59 | C27: ='Cash Flow'!C20+'Cash Flow'!C21+'Cash Flow'!C22+'Cash Flow'!C26 -> 33.95 | D27: ='Cash Flow'!D20+'Cash Flow'!D21+'Cash Flow'!D22+'Cash Flow'!D26 -> 36.73 | E27: ='Cash Flow'!E20+'Cash Flow'!E21+'Cash Flow'!E22+'Cash Flow'!E26 -> 49.12 | F27: ='Cash Flow'!F20+'Cash Flow'!F21+'Cash Flow'!F22+'Cash Flow'!F26 -> 51.28 | G27: ='Cash Flow'!G20+'Cash Flow'!G21+'Cash Flow'!G22+'Cash Flow'!G26 -> 41.78 | H27: ='Cash Flow'!H20+'Cash Flow'!H21+'Cash Flow'!H22+'Cash Flow'!H26 -> 46.59 | I27: ='Cash Flow'!I20+'Cash Flow'!I21+'Cash Flow'!I22+'Cash Flow'!I26 -> 59.53 | ... K27: ='Cash Flow'!K20+'Cash Flow'!K21+'Cash Flow'!K22+'Cash Flow'!K26 -> 50.42 | L27: =L5*L30 -> 43.785535 | M27: =M5*M30 -> 45.890905 | N27: =N5*N30 -> 47.868054 | O27: =O5*O30 -> 49.691046 | P27: =P5*P30 -> 51.335009
A28: D&A of Revenue | B28: =B27/B4 -> 0.097476045 | C28: =C27/C4 -> 0.076655603 | D28: =D27/D4 -> 0.077073191 | E28: =E27/E4 -> 0.096232588 | F28: =F27/F4 -> 0.097542418 | G28: =G27/G4 -> 0.074452919 | H28: =H27/H4 -> 0.074497514 | I28: =I27/I4 -> 0.08094364 | ... K28: =K27/K4 -> 0.09701191
A29: AVERAGE | B29: =AVERAGE(B28:K28) -> 0.084685607
A30: Growth Assumptions | L30: 0.08 | M30: 0.08 | N30: 0.08 | O30: 0.08 | P30: 0.08
A32: CHANGE IN WORKING CAPITAL
A33: Historical | L33: Projected
B34: 2015 | C34: 2016 | D34: 2017 | E34: 2018 | F34: 2019 | G34: 2020 | H34: 2021 | I34: 2022 | J34: 2023 | K34: 2024 | L34: 2025 | M34: 2026 | N34: 2027 | O34: 2028 | P34: 2029
A35: Net Working Capital | B35: =('Balance Sheet'!B22+'Balance Sheet'!B25+'Balance Sheet'!B26+'Balance Sheet'!B27) - ('Balance Sheet'!B82+'Balance Sheet'!B84+'Balance Sheet'!B85) -> 92.35 | C35: =('Balance Sheet'!C22+'Balance Sheet'!C25+'Balance Sheet'!C26+'Balance Sheet'!C27) - ('Balance Sheet'!C82+'Balance Sheet'!C84+'Balance Sheet'!C85) -> 82.06 | D35: =('Balance Sheet'!D22+'Balance Sheet'!D25+'Balance Sheet'!D26+'Balance Sheet'!D27) - ('Balance Sheet'!D82+'Balance Sheet'!D84+'Balance Sheet'!D85) -> 2.03 | E35: =('Balance Sheet'!E22+'Balance Sheet'!E25+'Balance Sheet'!E26+'Balance Sheet'!E27) - ('Balance Sheet'!E82+'Balance Sheet'!E84+'Balance Sheet'!E85) -> -50.12 | F35: =('Balance Sheet'!F22+'Balance Sheet'!F25+'Balance Sheet'!F26+'Balance Sheet'!F27) - ('Balance Sheet'!F82+'Balance Sheet'!F84+'Balance Sheet'!F85) -> -53.22 | G35: =('Balance Sheet'!G22+'Balance Sheet'!G25+'Balance Sheet'!G26+'Balance Sheet'!G27) - ('Balance Sheet'!G82+'Balance Sheet'!G84+'Balance Sheet'!G85) -> -68.48 | H35: =('Balance Sheet'!H22+'Balance Sheet'!H25+'Balance Sheet'!H26+'Balance Sheet'!H27) - ('Balance Sheet'!H82+'Balance Sheet'!H84+'Balance Sheet'!H85) -> -141.56 | I35: =('Balance Sheet'!I22+'Balance Sheet'!I25+'Balance Sheet'!I26+'Balance Sheet'!I27) - ('Balance Sheet'!I82+'Balance Sheet'!I84+'Balance Sheet'!I85) -> -154.44 | ... K35: =('Balance Sheet'!K22+'Balance Sheet'!K25+'Balance Sheet'!K26+'Balance Sheet'!K27) - ('Balance Sheet'!K82+'Balance Sheet'!K84+'Balance Sheet'!K85) -> -231.37
A36: Change in Working Capital | B36: =C35-B35 -> -10.29 | C36: =D35-C35 -> -80.03 | D36: =E35-D35 -> -52.15 | E36: =F35-E35 -> -3.1 | F36: =G35-F35 -> -15.26 | G36: =H35-G35 -> -73.08 | H36: =I35-H35 -> -12.88 | I36: =J35-I35 -> 39.53 | J36: =K35-J35 -> -116.46 | L36: =L5*$B$37 -> 2.7365959 | M36: =M5*$B$37 -> 2.8681815 | N36: =N5*$B$37 -> 2.9917534 | O36: =O5*$B$37 -> 3.1056904 | P36: =P5*$B$37 -> 3.2084381
A37: NWC Assumption Rate | B37: 0.005
A39: CAPITAL EXPENDITURE
A40: Historical | L40: Projected
B41: 2015 | C41: 2016 | D41: 2017 | E41: 2018 | F41: 2019 | G41: 2020 | H41: 2021 | I41: 2022 | J41: 2023 | K41: 2024 | L41: 2025 | M41: 2026 | N41: 2027 | O41: 2028 | P41: 2029
A42: CapEx (PPE & Intangibles) | B42: =-('Cash Flow'!B53+'Cash Flow'!B54) -> 14.06 | C42: =-('Cash Flow'!C53+'Cash Flow'!C54) -> 6.83 | D42: =-('Cash Flow'!D53+'Cash Flow'!D54) -> 12.41 | E42: =-('Cash Flow'!E53+'Cash Flow'!E54) -> 12.37 | F42: =-('Cash Flow'!F53+'Cash Flow'!F54) -> 5.94 | G42: =-('Cash Flow'!G53+'Cash Flow'!G54) -> 4.35 | H42: =-('Cash Flow'!H53+'Cash Flow'!H54) -> 10.62 | I42: =-('Cash Flow'!I53+'Cash Flow'!I54) -> 24.48 | ... K42: =-('Cash Flow'!K53+'Cash Flow'!K54) -> 7.45 | L42: =L45*L5 -> 8.2097878 | M42: =M45*M5 -> 8.6045446 | N42: =N45*N5 -> 8.9752602 | O42: =O45*O5 -> 9.3170712 | P42: =P45*P5 -> 9.6253142
A43: CapEx % of Revenue | B43: =B42/B4 -> 0.033764799 | C43: =C42/C4 -> 0.015421436 | D43: =D42/D4 -> 0.026040792 | E43: =E42/E4 -> 0.024234469 | F43: =F42/F4 -> 0.01129879 | G43: =G42/G4 -> 0.0077517998 | H43: =H42/H4 -> 0.016981404 | I43: =I42/I4 -> 0.033285743 | ... K43: =K42/K4 -> 0.014334366
A44: AVERAGE | B44: =AVERAGE(B43:K43) -> 0.019927477
A45: Growth Assumptions | L45: 0.015 | M45: 0.015 | N45: 0.015 | O45: 0.015 | P45: 0.015

Sheet DCF_Pro_Forma
A1: Input and Assumptions
J2: Cells in YELLOW are input
A3: Last Updated on | B3: =DCF_CSCF!B3 -> 46073
A4: Last Financial Statement Date | B4: ='Balance Sheet'!K18 -> 30-12-2024 | J4: Cells in BEIGE are looked up
A5: Current Market Price | B5: =DCF_CSCF!B5 -> 40.25
A6: # of share outstanding in million | B6: =DCF_CSCF!B6 -> 40.4 | J6: Cells in WHITE are calculated
A7: Growth rate of FCF (long term growth) | B7: 0.02
A8: Discount rate (WACC) | B8: 0.0741
A9: Inflation | B9: 0.025
A10: Assumption on the average growth rate of | B10: =(Process_Pro_Forma!B6+B9)/2 -> 0.053083687
A11: Industry Tax Rate | B11: 0.2
A14: Effective Tax Rate | B14: =Process_Pro_Forma!B22 -> 0.25
A16: Investment Criteria
A18: Decision | B18: Difference Between Value and Price
A19: Sell | B19: =ROUND((B45-B5) / B5, 3) -> -0.469 | C19: {=_xlfn.IFS(B19>0.1,"BUY",B19<-0.1,"SELL",TRUE,"HOLD")} -> SELL
A20: Underperform
A21: HOLD
A22: BUY
A23: Strong Buy
A25: Free Cash Flow Projection
A27: Year | B27: Today | C27: Yr 1 | D27: Yr 2 | E27: Yr 3 | F27: Yr 4 | G27: Yr 5 | H27: Terminal Value @ Yr 5
A28: EBIT (Operating Income) | C28: {=Process_Pro_Forma!L12:P12} -> 32.839151 | D28: 34.418179 | E28: 35.901041 | F28: 37.268285 | G28: 38.501257
A29: Tax Rate | C29: =$B$14 -> 0.25 | D29: =$B$14 -> 0.25 | E29: =$B$14 -> 0.25 | F29: =$B$14 -> 0.25 | G29: =$B$14 -> 0.25
A30: NOPAT | C30: =C28*(1-C29) -> 24.629363 | D30: =D28*(1-D29) -> 25.813634 | E30: =E28*(1-E29) -> 26.92578 | F30: =F28*(1-F29) -> 27.951213 | G30: =G28*(1-G29) -> 28.875943
A31: Depreciation and Other non-cash items | C31: {=Process_Pro_Forma!L27:P27} -> 43.785535 | D31: 45.890905 | E31: 47.868054 | F31: 49.691046 | G31: 51.335009
A32: Change in NWC | C32: {=Process_Pro_Forma!L36:P36} -> 2.7365959 | D32: 2.8681815 | E32: 2.9917534 | F32: 3.1056904 | G32: 3.2084381
A33: Capital expenditure | C33: {=Process_Pro_Forma!L42:P42} -> 8.2097878 | D33: 8.6045446 | E33: 8.9752602 | F33: 9.3170712 | G33: 9.6253142
A34: FCF | C34: =(C30+C31)-(C32+C33) -> 57.468514 | D34: =(D30+D31)-(D32+D33) -> 60.231813 | E34: =(E30+E31)-(E32+E33) -> 62.826821 | F34: =(F30+F31)-(F32+F33) -> 65.219498 | G34: =(G30+G31)-(G32+G33) -> 67.3772
A35: FCF with Terminal Value | C35: {=C34:G34} -> 57.468514 | D35: 60.231813 | E35: 62.826821 | F35: 65.219498 | G35: 67.3772 | H35: =G35*(1+B7) / (B8-B7) -> 1270.328
A36: Present Value | C36: =C35/(1+$B$8)^1 -> 53.503877 | D36: =D35/(1+$B$8)^2 -> 52.207933 | E36: =E35/(1+$B$8)^3 -> 50.700348 | F36: =F35/(1+$B$8)^4 -> 49.000283 | G36: =G35/(1+$B$8)^5 -> 47.129125 | H36: =H35/(1+$B$8)^5 -> 888.5713
A39: Free Cash Flow Projection
A41: Enterprise Value | B41: =SUM(C36:H36) -> 1141.1129
A42: Firm Cash | B42: =DCF_CSCF!B34 -> 41.88
A43: Firm Debt | B43: =DCF_CSCF!B35 -> 319.65
A44: Equity Value | B44: =(B41+B42)-B43 -> 863.34286
A45: Fair Share Price | B45: =B44/B6 -> 21.369873
A46: Recommendation | B46: SELL
A50: Sensitivity Analysis
A51: Terminal Growth Rate vs Discount Rate (CSCF)
B55: Scenario 1: Discount Rate ±10% | C55: WACC | D55: Fair Price
...

Sheet CCA
A1: Input and Assumptions
I2: Cells in YELLOW are input
A3: Last Updated on | B3: =DCF_Pro_Forma!B3 -> 46073
A4: Last Financial Statement Date | B4: ='Balance Sheet'!K18 -> 30-12-2024 | I4: Cells in BEIGE are looked up
A5: Current Market Price | B5: =DCF_Pro_Forma!B5 -> 40.25
A6: # of share outstanding in million | B6: =DCF_Pro_Forma!B6 -> 40.4 | I6: Cells in WHITE are calculated
A7: Comparable Companies | B7: Company 1 | C7: Company 2 | D7: Company 3 | E7: Company 4 | F7: Company 5
A8: Mutiples Ratios at | B8: Colliers International | C8: FirstService Corp | D8: CBRE Group | E8: Jones Lang LaSalle | F8: Real Matters Inc | I8: Cells in RED are output
A9: Total Enterprise Value (TEV)/Revenue | B9: 1.22 | C9: 1.47 | D9: 1.04 | E9: 0.72 | F9: 4.41
A10: TEV/EBITDA | B10: 9.26 | C10: 14.3 | D10: 12.58 | E10: 9.79 | F10: 22.64
A11: P/E | B11: 15.24 | C11: 25.17 | D11: 19.91 | E11: 15 | F11: 33.82
A13: Your Company Information
A14: Revenue | B14: ='Income Statement'!K20 -> 519.73
A15: EBITDA | B15: ='Income Statement'!K46+'Income Statement'!K34+'Income Statement'!K35+'Income Statement'!K36 -> 52.97
A16: Earnings per share | B16: ='Income Statement'!K94 -> 0.29
A18: Investment Criteria
A20: Decision | B20: Difference Between Value and Price
A21: Sell | B21: =ROUND((B46-B5) / B5, 3) -> -0.781 | C21: {=_xlfn.IFS(B21>0.1,"BUY",B21<-0.1,"SELL",TRUE,"HOLD")} -> SELL
A22: Underperform
A23: HOLD
A24: BUY
A25: Strong Buy
A28: Average Multiple
B30: average | C30: median | D30: your company
A31: TEV/Revenue | B31: =AVERAGE(B9:F9) -> 1.772 | C31: =MEDIAN(B9:F9) -> 1.22 | D31: 2.16
A32: TEV/EBITDA | B32: =AVERAGE(B10:F10) -> 13.714 | C32: =MEDIAN(B10:F10) -> 12.58 | D32: 9.32
A33: P/E | B33: =AVERAGE(B11:F11) -> 21.828 | C33: =MEDIAN(B11:F11) -> 19.91 | D33: 17.7
A39: Free Cash Flow Projection
A41: implied by | B41: TEV/Revenue | C41: TEV/EBITDA | D41: Implied Share Price (P/E)
A42: Enterprise Value | B42: =C31*B14 -> 634.0706 | C42: =C32*B15 -> 666.3626
A43: Firm Cash | B43: =DCF_Pro_Forma!B42 -> 41.88 | C43: 42
A44: Firm Debt | B44: =DCF_Pro_Forma!B43 -> 319.65 | C44: 320
A45: Equity Value | B45: =B42+B43-B44 -> 356.3006 | C45: =C42+C43-C44 -> 388.3626
A46: Fair Share Price | B46: =B45/B6 -> 8.8193218 | C46: =C45/B6 -> 9.6129356 | D46: =C33*B16 -> 5.7739
A47: Recommendation | B47: SELL | C47: SELL | D47: SELL
